Workbook

Sheet Resumo
C2: Earnings do Ibovespa e sensibilidades macro
C3: Consolidação das análises contemporâneas do índice e dos setores. Dados disponíveis até setembro de 2026; macro até agosto de 2026.
C6: Cobertura e especificação principal
C7: Item | D7: Valor | E7: Unidade | F7: Observação
C8: Cobertura setorial - início | D8: =MIN('Earnings 12M Fwd'!$C$7:$C$231) | E8: mês | F8: Séries GICS consolidadas
C9: Cobertura setorial - fim | D9: =MAX('Earnings 12M Fwd'!$C$7:$C$231) | E9: mês | F9: Séries GICS consolidadas
C10: Número de observações | D10: =COUNTA('Earnings 12M Fwd'!$C$7:$C$231) | E10: meses | F10: Earnings setoriais
C11: Modelo principal | D11: ex_2013_14 | E11: amostra | F11: Exclui 2013-2014
C14: Modelo contemporâneo do IBOV - BEst EPS direto
C15: Variável | D15: Beta | E15: Beta padronizado | F15: p-valor HAC | G15: Leitura | H15: Amostra
C16: Focus PIB | D16: =SUMIFS('Reg IBOV'!$J$7:$J$26,'Reg IBOV'!$D$7:$D$26,"ex_2013_14",'Reg IBOV'!$I$7:$I$26,"d_focus_pib3") | E16: =SUMIFS('Reg IBOV'!$K$7:$K$26,'Reg IBOV'!$D$7:$D$26,"ex_2013_14",'Reg IBOV'!$I$7:$I$26,"d_focus_pib3") | F16: =SUMIFS('Reg IBOV'!$N$7:$N$26,'Reg IBOV'!$D$7:$D$26,"ex_2013_14",'Reg IBOV'!$I$7:$I$26,"d_focus_pib3") | G16: Principal driver contemporâneo | H16: ex_2013_14
C17: BCOM em USD | D17: =SUMIFS('Reg IBOV'!$J$7:$J$26,'Reg IBOV'!$D$7:$D$26,"ex_2013_14",'Reg IBOV'!$I$7:$I$26,"d_bcom_usd3") | E17: =SUMIFS('Reg IBOV'!$K$7:$K$26,'Reg IBOV'!$D$7:$D$26,"ex_2013_14",'Reg IBOV'!$I$7:$I$26,"d_bcom_usd3") | F17: =SUMIFS('Reg IBOV'!$N$7:$N$26,'Reg IBOV'!$D$7:$D$26,"ex_2013_14",'Reg IBOV'!$I$7:$I$26,"d_bcom_usd3") | G17: Sem significância no modelo completo | H17: ex_2013_14
C18: USD/BRL | D18: =SUMIFS('Reg IBOV'!$J$7:$J$26,'Reg IBOV'!$D$7:$D$26,"ex_2013_14",'Reg IBOV'!$I$7:$I$26,"d_usdbrl3") | E18: =SUMIFS('Reg IBOV'!$K$7:$K$26,'Reg IBOV'!$D$7:$D$26,"ex_2013_14",'Reg IBOV'!$I$7:$I$26,"d_usdbrl3") | F18: =SUMIFS('Reg IBOV'!$N$7:$N$26,'Reg IBOV'!$D$7:$D$26,"ex_2013_14",'Reg IBOV'!$I$7:$I$26,"d_usdbrl3") | G18: Sem significância no modelo completo | H18: ex_2013_14
C19: IPCA realizado 12m | D19: =SUMIFS('Reg IBOV'!$J$7:$J$26,'Reg IBOV'!$D$7:$D$26,"ex_2013_14",'Reg IBOV'!$I$7:$I$26,"d_ipca12_3_available") | E19: =SUMIFS('Reg IBOV'!$K$7:$K$26,'Reg IBOV'!$D$7:$D$26,"ex_2013_14",'Reg IBOV'!$I$7:$I$26,"d_ipca12_3_available") | F19: =SUMIFS('Reg IBOV'!$N$7:$N$26,'Reg IBOV'!$D$7:$D$26,"ex_2013_14",'Reg IBOV'!$I$7:$I$26,"d_ipca12_3_available") | G19: Significância marginal | H19: ex_2013_14
C20: Swap pré-DI 360d | D20: =SUMIFS('Reg IBOV'!$J$7:$J$26,'Reg IBOV'!$D$7:$D$26,"ex_2013_14",'Reg IBOV'!$I$7:$I$26,"d_swap360_3") | E20: =SUMIFS('Reg IBOV'!$K$7:$K$26,'Reg IBOV'!$D$7:$D$26,"ex_2013_14",'Reg IBOV'!$I$7:$I$26,"d_swap360_3") | F20: =SUMIFS('Reg IBOV'!$N$7:$N$26,'Reg IBOV'!$D$7:$D$26,"ex_2013_14",'Reg IBOV'!$I$7:$I$26,"d_swap360_3") | G20: Sinal positivo, mas instável entre janelas | H20: ex_2013_14
C21: R² do modelo | D21: =SUMIFS('Reg IBOV'!$G$7:$G$26,'Reg IBOV'!$D$7:$D$26,"ex_2013_14",'Reg IBOV'!$I$7:$I$26,"d_focus_pib3") | G21: Poder explicativo do modelo completo | H21: ex_2013_14
C24: Conclusões até aqui
C25: Tema | D25: Evidência | E25: Valor | F25: Unidade | G25: Interpretação | H25: Referência
C26: Focus PIB | D26: Beta padronizado do IBOV | E26: =E16 | F26: desvios-padrão | G26: É o driver mais consistente do índice. | H26: Reg IBOV
C27: Inflação | D27: ΔR²: IPCA realizado menos Focus | E27: =SUMIFS('Inflacao'!$K$15:$K$26,'Inflacao'!$C$15:$C$26,"ex_2013_14",'Inflacao'!$D$15:$D$26,"d_ipca12_3_available")-SUMIFS('Inflacao'!$K$15:$K$26,'Inflacao'!$C$15:$C$26,"ex_2013_14",'Inflacao'!$D$15:$D$26,"d_focus_ipca3") | F27: p.p. de R² | G27: O realizado melhora um pouco o ajuste, mas a diferença é pequena. | H27: Inflacao
C28: Swap pré-DI | D28: Beta na amostra limpa | E28: =SUMIFS('Swap Robustez'!$H$21:$H$68,'Swap Robustez'!$C$21:$C$68,"IBOV BEst EPS",'Swap Robustez'!$D$21:$D$68,"clean",'Swap Robustez'!$E$21:$E$68,"full") | F28: % revisão por 1 p.p. | G28: O sinal positivo não é robusto o suficiente para leitura causal. | H28: Swap Robustez
C29: Setores | D29: Maior beta Focus padronizado | E29: =SUMIFS('Reg Setores'!$L$7:$L$114,'Reg Setores'!$D$7:$D$114,"ex_2013_14",'Reg Setores'!$C$7:$C$114,"Energy") | F29: desvios-padrão | G29: Energia lidera na amostra principal. | H29: Painel Setorial
C30: Ex-commodities | D30: Diferença de beta vs. IBOV | E30: =SUMIFS('Ex-Commodities'!$Q$19:$Q$24,'Ex-Commodities'!$C$19:$C$24,"ex_2013_14") | F30: % revisão por 1 p.p. | G30: O beta ex-commodities é menor, não maior. | H30: Ex-Commodities
C31: Energia | D31: Correlação das revisions com Petrobras | E31: 0.995009 | F31: correlação | G31: A liderança de Energia é majoritariamente Petrobras. | H31: Energia
C33: Nota metodológica | D33: As regressões são contemporâneas e associativas. Coeficientes não devem ser lidos como efeitos causais. Resultados setoriais usam BEst Net Income agregado; o modelo direto do índice usa BEst EPS.

Sheet Painel Setorial
C2: Sensibilidades contemporâneas por setor
C3: Amostra principal exclui 2013-2014. Betas padronizados permitem comparar a magnitude entre setores.
C6: Resultados do modelo completo
C8: Setor | D8: R² | E8: Focus beta | F8: Focus beta pad. | G8: Focus p | H8: Focus q BH | I8: Swap beta | J8: Swap beta pad. | K8: Swap p | L8: Swap q BH
C9: Energy | D9: =SUMIFS('Reg Setores'!$H$7:$H$114,'Reg Setores'!$D$7:$D$114,"ex_2013_14",'Reg Setores'!$C$7:$C$114,$C9) | E9: =SUMIFS('Reg Setores'!$K$7:$K$114,'Reg Setores'!$D$7:$D$114,"ex_2013_14",'Reg Setores'!$C$7:$C$114,$C9) | F9: =SUMIFS('Reg Setores'!$L$7:$L$114,'Reg Setores'!$D$7:$D$114,"ex_2013_14",'Reg Setores'!$C$7:$C$114,$C9) | G9: =SUMIFS('Reg Setores'!$N$7:$N$114,'Reg Setores'!$D$7:$D$114,"ex_2013_14",'Reg Setores'!$C$7:$C$114,$C9) | H9: =SUMIFS('Reg Setores'!$AM$7:$AM$114,'Reg Setores'!$D$7:$D$114,"ex_2013_14",'Reg Setores'!$C$7:$C$114,$C9) | I9: =SUMIFS('Reg Setores'!$AE$7:$AE$114,'Reg Setores'!$D$7:$D$114,"ex_2013_14",'Reg Setores'!$C$7:$C$114,$C9) | J9: =SUMIFS('Reg Setores'!$AF$7:$AF$114,'Reg Setores'!$D$7:$D$114,"ex_2013_14",'Reg Setores'!$C$7:$C$114,$C9) | K9: =SUMIFS('Reg Setores'!$AH$7:$AH$114,'Reg Setores'!$D$7:$D$114,"ex_2013_14",'Reg Setores'!$C$7:$C$114,$C9) | L9: =SUMIFS('Reg Setores'!$AQ$7:$AQ$114,'Reg Setores'!$D$7:$D$114,"ex_2013_14",'Reg Setores'!$C$7:$C$114,$C9)
C10: Real Estate | D10: =SUMIFS('Reg Setores'!$H$7:$H$114,'Reg Setores'!$D$7:$D$114,"ex_2013_14",'Reg Setores'!$C$7:$C$114,$C10) | E10: =SUMIFS('Reg Setores'!$K$7:$K$114,'Reg Setores'!$D$7:$D$114,"ex_2013_14",'Reg Setores'!$C$7:$C$114,$C10) | F10: =SUMIFS('Reg Setores'!$L$7:$L$114,'Reg Setores'!$D$7:$D$114,"ex_2013_14",'Reg Setores'!$C$7:$C$114,$C10) | G10: =SUMIFS('Reg Setores'!$N$7:$N$114,'Reg Setores'!$D$7:$D$114,"ex_2013_14",'Reg Setores'!$C$7:$C$114,$C10) | H10: =SUMIFS('Reg Setores'!$AM$7:$AM$114,'Reg Setores'!$D$7:$D$114,"ex_2013_14",'Reg Setores'!$C$7:$C$114,$C10) | I10: =SUMIFS('Reg Setores'!$AE$7:$AE$114,'Reg Setores'!$D$7:$D$114,"ex_2013_14",'Reg Setores'!$C$7:$C$114,$C10) | J10: =SUMIFS('Reg Setores'!$AF$7:$AF$114,'Reg Setores'!$D$7:$D$114,"ex_2013_14",'Reg Setores'!$C$7:$C$114,$C10) | K10: =SUMIFS('Reg Setores'!$AH$7:$AH$114,'Reg Setores'!$D$7:$D$114,"ex_2013_14",'Reg Setores'!$C$7:$C$114,$C10) | L10: =SUMIFS('Reg Setores'!$AQ$7:$AQ$114,'Reg Setores'!$D$7:$D$114,"ex_2013_14",'Reg Setores'!$C$7:$C$114,$C10)
C11: Consumer Discretionary | D11: =SUMIFS('Reg Setores'!$H$7:$H$114,'Reg Setores'!$D$7:$D$114,"ex_2013_14",'Reg Setores'!$C$7:$C$114,$C11) | E11: =SUMIFS('Reg Setores'!$K$7:$K$114,'Reg Setores'!$D$7:$D$114,"ex_2013_14",'Reg Setores'!$C$7:$C$114,$C11) | F11: =SUMIFS('Reg Setores'!$L$7:$L$114,'Reg Setores'!$D$7:$D$114,"ex_2013_14",'Reg Setores'!$C$7:$C$114,$C11) | G11: =SUMIFS('Reg Setores'!$N$7:$N$114,'Reg Setores'!$D$7:$D$114,"ex_2013_14",'Reg Setores'!$C$7:$C$114,$C11) | H11: =SUMIFS('Reg Setores'!$AM$7:$AM$114,'Reg Setores'!$D$7:$D$114,"ex_2013_14",'Reg Setores'!$C$7:$C$114,$C11) | I11: =SUMIFS('Reg Setores'!$AE$7:$AE$114,'Reg Setores'!$D$7:$D$114,"ex_2013_14",'Reg Setores'!$C$7:$C$114,$C11) | J11: =SUMIFS('Reg Setores'!$AF$7:$AF$114,'Reg Setores'!$D$7:$D$114,"ex_2013_14",'Reg Setores'!$C$7:$C$114,$C11) | K11: =SUMIFS('Reg Setores'!$AH$7:$AH$114,'Reg Setores'!$D$7:$D$114,"ex_2013_14",'Reg Setores'!$C$7:$C$114,$C11) | L11: =SUMIFS('Reg Setores'!$AQ$7:$AQ$114,'Reg Setores'!$D$7:$D$114,"ex_2013_14",'Reg Setores'!$C$7:$C$114,$C11)
C12: Industrials | D12: =SUMIFS('Reg Setores'!$H$7:$H$114,'Reg Setores'!$D$7:$D$114,"ex_2013_14",'Reg Setores'!$C$7:$C$114,$C12) | E12: =SUMIFS('Reg Setores'!$K$7:$K$114,'Reg Setores'!$D$7:$D$114,"ex_2013_14",'Reg Setores'!$C$7:$C$114,$C12) | F12: =SUMIFS('Reg Setores'!$L$7:$L$114,'Reg Setores'!$D$7:$D$114,"ex_2013_14",'Reg Setores'!$C$7:$C$114,$C12) | G12: =SUMIFS('Reg Setores'!$N$7:$N$114,'Reg Setores'!$D$7:$D$114,"ex_2013_14",'Reg Setores'!$C$7:$C$114,$C12) | H12: =SUMIFS('Reg Setores'!$AM$7:$AM$114,'Reg Setores'!$D$7:$D$114,"ex_2013_14",'Reg Setores'!$C$7:$C$114,$C12) | I12: =SUMIFS('Reg Setores'!$AE$7:$AE$114,'Reg Setores'!$D$7:$D$114,"ex_2013_14",'Reg Setores'!$C$7:$C$114,$C12) | J12: =SUMIFS('Reg Setores'!$AF$7:$AF$114,'Reg Setores'!$D$7:$D$114,"ex_2013_14",'Reg Setores'!$C$7:$C$114,$C12) | K12: =SUMIFS('Reg Setores'!$AH$7:$AH$114,'Reg Setores'!$D$7:$D$114,"ex_2013_14",'Reg Setores'!$C$7:$C$114,$C12) | L12: =SUMIFS('Reg Setores'!$AQ$7:$AQ$114,'Reg Setores'!$D$7:$D$114,"ex_2013_14",'Reg Setores'!$C$7:$C$114,$C12)
C13: Financials | D13: =SUMIFS('Reg Setores'!$H$7:$H$114,'Reg Setores'!$D$7:$D$114,"ex_2013_14",'Reg Setores'!$C$7:$C$114,$C13) | E13: =SUMIFS('Reg Setores'!$K$7:$K$114,'Reg Setores'!$D$7:$D$114,"ex_2013_14",'Reg Setores'!$C$7:$C$114,$C13) | F13: =SUMIFS('Reg Setores'!$L$7:$L$114,'Reg Setores'!$D$7:$D$114,"ex_2013_14",'Reg Setores'!$C$7:$C$114,$C13) | G13: =SUMIFS('Reg Setores'!$N$7:$N$114,'Reg Setores'!$D$7:$D$114,"ex_2013_14",'Reg Setores'!$C$7:$C$114,$C13) | H13: =SUMIFS('Reg Setores'!$AM$7:$AM$114,'Reg Setores'!$D$7:$D$114,"ex_2013_14",'Reg Setores'!$C$7:$C$114,$C13) | I13: =SUMIFS('Reg Setores'!$AE$7:$AE$114,'Reg Setores'!$D$7:$D$114,"ex_2013_14",'Reg Setores'!$C$7:$C$114,$C13) | J13: =SUMIFS('Reg Setores'!$AF$7:$AF$114,'Reg Setores'!$D$7:$D$114,"ex_2013_14",'Reg Setores'!$C$7:$C$114,$C13) | K13: =SUMIFS('Reg Setores'!$AH$7:$AH$114,'Reg Setores'!$D$7:$D$114,"ex_2013_14",'Reg Setores'!$C$7:$C$114,$C13) | L13: =SUMIFS('Reg Setores'!$AQ$7:$AQ$114,'Reg Setores'!$D$7:$D$114,"ex_2013_14",'Reg Setores'!$C$7:$C$114,$C13)
C14: Materials | D14: =SUMIFS('Reg Setores'!$H$7:$H$114,'Reg Setores'!$D$7:$D$114,"ex_2013_14",'Reg Setores'!$C$7:$C$114,$C14) | E14: =SUMIFS('Reg Setores'!$K$7:$K$114,'Reg Setores'!$D$7:$D$114,"ex_2013_14",'Reg Setores'!$C$7:$C$114,$C14) | F14: =SUMIFS('Reg Setores'!$L$7:$L$114,'Reg Setores'!$D$7:$D$114,"ex_2013_14",'Reg Setores'!$C$7:$C$114,$C14) | G14: =SUMIFS('Reg Setores'!$N$7:$N$114,'Reg Setores'!$D$7:$D$114,"ex_2013_14",'Reg Setores'!$C$7:$C$114,$C14) | H14: =SUMIFS('Reg Setores'!$AM$7:$AM$114,'Reg Setores'!$D$7:$D$114,"ex_2013_14",'Reg Setores'!$C$7:$C$114,$C14) | I14: =SUMIFS('Reg Setores'!$AE$7:$AE$114,'Reg Setores'!$D$7:$D$114,"ex_2013_14",'Reg Setores'!$C$7:$C$114,$C14) | J14: =SUMIFS('Reg Setores'!$AF$7:$AF$114,'Reg Setores'!$D$7:$D$114,"ex_2013_14",'Reg Setores'!$C$7:$C$114,$C14) | K14: =SUMIFS('Reg Setores'!$AH$7:$AH$114,'Reg Setores'!$D$7:$D$114,"ex_2013_14",'Reg Setores'!$C$7:$C$114,$C14) | L14: =SUMIFS('Reg Setores'!$AQ$7:$AQ$114,'Reg Setores'!$D$7:$D$114,"ex_2013_14",'Reg Setores'!$C$7:$C$114,$C14)
C15: Utilities | D15: =SUMIFS('Reg Setores'!$H$7:$H$114,'Reg Setores'!$D$7:$D$114,"ex_2013_14",'Reg Setores'!$C$7:$C$114,$C15) | E15: =SUMIFS('Reg Setores'!$K$7:$K$114,'Reg Setores'!$D$7:$D$114,"ex_2013_14",'Reg Setores'!$C$7:$C$114,$C15) | F15: =SUMIFS('Reg Setores'!$L$7:$L$114,'Reg Setores'!$D$7:$D$114,"ex_2013_14",'Reg Setores'!$C$7:$C$114,$C15) | G15: =SUMIFS('Reg Setores'!$N$7:$N$114,'Reg Setores'!$D$7:$D$114,"ex_2013_14",'Reg Setores'!$C$7:$C$114,$C15) | H15: =SUMIFS('Reg Setores'!$AM$7:$AM$114,'Reg Setores'!$D$7:$D$114,"ex_2013_14",'Reg Setores'!$C$7:$C$114,$C15) | I15: =SUMIFS('Reg Setores'!$AE$7:$AE$114,'Reg Setores'!$D$7:$D$114,"ex_2013_14",'Reg Setores'!$C$7:$C$114,$C15) | J15: =SUMIFS('Reg Setores'!$AF$7:$AF$114,'Reg Setores'!$D$7:$D$114,"ex_2013_14",'Reg Setores'!$C$7:$C$114,$C15) | K15: =SUMIFS('Reg Setores'!$AH$7:$AH$114,'Reg Setores'!$D$7:$D$114,"ex_2013_14",'Reg Setores'!$C$7:$C$114,$C15) | L15: =SUMIFS('Reg Setores'!$AQ$7:$AQ$114,'Reg Setores'!$D$7:$D$114,"ex_2013_14",'Reg Setores'!$C$7:$C$114,$C15)
C16: Consumer Staples | D16: =SUMIFS('Reg Setores'!$H$7:$H$114,'Reg Setores'!$D$7:$D$114,"ex_2013_14",'Reg Setores'!$C$7:$C$114,$C16) | E16: =SUMIFS('Reg Setores'!$K$7:$K$114,'Reg Setores'!$D$7:$D$114,"ex_2013_14",'Reg Setores'!$C$7:$C$114,$C16) | F16: =SUMIFS('Reg Setores'!$L$7:$L$114,'Reg Setores'!$D$7:$D$114,"ex_2013_14",'Reg Setores'!$C$7:$C$114,$C16) | G16: =SUMIFS('Reg Setores'!$N$7:$N$114,'Reg Setores'!$D$7:$D$114,"ex_2013_14",'Reg Setores'!$C$7:$C$114,$C16) | H16: =SUMIFS('Reg Setores'!$AM$7:$AM$114,'Reg Setores'!$D$7:$D$114,"ex_2013_14",'Reg Setores'!$C$7:$C$114,$C16) | I16: =SUMIFS('Reg Setores'!$AE$7:$AE$114,'Reg Setores'!$D$7:$D$114,"ex_2013_14",'Reg Setores'!$C$7:$C$114,$C16) | J16: =SUMIFS('Reg Setores'!$AF$7:$AF$114,'Reg Setores'!$D$7:$D$114,"ex_2013_14",'Reg Setores'!$C$7:$C$114,$C16) | K16: =SUMIFS('Reg Setores'!$AH$7:$AH$114,'Reg Setores'!$D$7:$D$114,"ex_2013_14",'Reg Setores'!$C$7:$C$114,$C16) | L16: =SUMIFS('Reg Setores'!$AQ$7:$AQ$114,'Reg Setores'!$D$7:$D$114,"ex_2013_14",'Reg Setores'!$C$7:$C$114,$C16)
C17: Health Care | D17: =SUMIFS('Reg Setores'!$H$7:$H$114,'Reg Setores'!$D$7:$D$114,"ex_2013_14",'Reg Setores'!$C$7:$C$114,$C17) | E17: =SUMIFS('Reg Setores'!$K$7:$K$114,'Reg Setores'!$D$7:$D$114,"ex_2013_14",'Reg Setores'!$C$7:$C$114,$C17) | F17: =SUMIFS('Reg Setores'!$L$7:$L$114,'Reg Setores'!$D$7:$D$114,"ex_2013_14",'Reg Setores'!$C$7:$C$114,$C17) | G17: =SUMIFS('Reg Setores'!$N$7:$N$114,'Reg Setores'!$D$7:$D$114,"ex_2013_14",'Reg Setores'!$C$7:$C$114,$C17) | H17: =SUMIFS('Reg Setores'!$AM$7:$AM$114,'Reg Setores'!$D$7:$D$114,"ex_2013_14",'Reg Setores'!$C$7:$C$114,$C17) | I17: =SUMIFS('Reg Setores'!$AE$7:$AE$114,'Reg Setores'!$D$7:$D$114,"ex_2013_14",'Reg Setores'!$C$7:$C$114,$C17) | J17: =SUMIFS('Reg Setores'!$AF$7:$AF$114,'Reg Setores'!$D$7:$D$114,"ex_2013_14",'Reg Setores'!$C$7:$C$114,$C17) | K17: =SUMIFS('Reg Setores'!$AH$7:$AH$114,'Reg Setores'!$D$7:$D$114,"ex_2013_14",'Reg Setores'!$C$7:$C$114,$C17) | L17: =SUMIFS('Reg Setores'!$AQ$7:$AQ$114,'Reg Setores'!$D$7:$D$114,"ex_2013_14",'Reg Setores'!$C$7:$C$114,$C17)
C18: Communication Services | D18: =SUMIFS('Reg Setores'!$H$7:$H$114,'Reg Setores'!$D$7:$D$114,"ex_2013_14",'Reg Setores'!$C$7:$C$114,$C18) | E18: =SUMIFS('Reg Setores'!$K$7:$K$114,'Reg Setores'!$D$7:$D$114,"ex_2013_14",'Reg Setores'!$C$7:$C$114,$C18) | F18: =SUMIFS('Reg Setores'!$L$7:$L$114,'Reg Setores'!$D$7:$D$114,"ex_2013_14",'Reg Setores'!$C$7:$C$114,$C18) | G18: =SUMIFS('Reg Setores'!$N$7:$N$114,'Reg Setores'!$D$7:$D$114,"ex_2013_14",'Reg Setores'!$C$7:$C$114,$C18) | H18: =SUMIFS('Reg Setores'!$AM$7:$AM$114,'Reg Setores'!$D$7:$D$114,"ex_2013_14",'Reg Setores'!$C$7:$C$114,$C18) | I18: =SUMIFS('Reg Setores'!$AE$7:$AE$114,'Reg Setores'!$D$7:$D$114,"ex_2013_14",'Reg Setores'!$C$7:$C$114,$C18) | J18: =SUMIFS('Reg Setores'!$AF$7:$AF$114,'Reg Setores'!$D$7:$D$114,"ex_2013_14",'Reg Setores'!$C$7:$C$114,$C18) | K18: =SUMIFS('Reg Setores'!$AH$7:$AH$114,'Reg Setores'!$D$7:$D$114,"ex_2013_14",'Reg Setores'!$C$7:$C$114,$C18) | L18: =SUMIFS('Reg Setores'!$AQ$7:$AQ$114,'Reg Setores'!$D$7:$D$114,"ex_2013_14",'Reg Setores'!$C$7:$C$114,$C18)
C19: Information Technology | D19: =SUMIFS('Reg Setores'!$H$7:$H$114,'Reg Setores'!$D$7:$D$114,"ex_2013_14",'Reg Setores'!$C$7:$C$114,$C19) | E19: =SUMIFS('Reg Setores'!$K$7:$K$114,'Reg Setores'!$D$7:$D$114,"ex_2013_14",'Reg Setores'!$C$7:$C$114,$C19) | F19: =SUMIFS('Reg Setores'!$L$7:$L$114,'Reg Setores'!$D$7:$D$114,"ex_2013_14",'Reg Setores'!$C$7:$C$114,$C19) | G19: =SUMIFS('Reg Setores'!$N$7:$N$114,'Reg Setores'!$D$7:$D$114,"ex_2013_14",'Reg Setores'!$C$7:$C$114,$C19) | H19: =SUMIFS('Reg Setores'!$AM$7:$AM$114,'Reg Setores'!$D$7:$D$114,"ex_2013_14",'Reg Setores'!$C$7:$C$114,$C19) | I19: =SUMIFS('Reg Setores'!$AE$7:$AE$114,'Reg Setores'!$D$7:$D$114,"ex_2013_14",'Reg Setores'!$C$7:$C$114,$C19) | J19: =SUMIFS('Reg Setores'!$AF$7:$AF$114,'Reg Setores'!$D$7:$D$114,"ex_2013_14",'Reg Setores'!$C$7:$C$114,$C19) | K19: =SUMIFS('Reg Setores'!$AH$7:$AH$114,'Reg Setores'!$D$7:$D$114,"ex_2013_14",'Reg Setores'!$C$7:$C$114,$C19) | L19: =SUMIFS('Reg Setores'!$AQ$7:$AQ$114,'Reg Setores'!$D$7:$D$114,"ex_2013_14",'Reg Setores'!$C$7:$C$114,$C19)
C22: Leitura | D22: Energy | E22: Consumer Discretionary | F22: Financials | G22: Materials
C23: Focus q BH < 10% | D23: Sim | E23: Sim | F23: Sim | G23: Sim
C24: Swap q BH < 10% | D24: Não | E24: Não | F24: Não | G24: Não
C25: Conclusão | D25: Energia lidera, mas o resultado é concentrado em Petrobras.

Sheet Sens Focus-Swap
C2: Matriz de sensibilidade: Focus PIB e swap pré-DI
C3: Impacto estimado sobre a revisão de earnings de três meses do BEst EPS do IBOV. Amostra ex_2013_14.
C6: Parâmetros do modelo
C7: Parâmetro | D7: Valor | E7: p-valor HAC | F7: Unidade | G7: Observação
C8: Beta Focus PIB | D8: =SUMIFS('Reg IBOV'!$J$7:$J$26,'Reg IBOV'!$D$7:$D$26,"ex_2013_14",'Reg IBOV'!$I$7:$I$26,"d_focus_pib3") | E8: =SUMIFS('Reg IBOV'!$N$7:$N$26,'Reg IBOV'!$D$7:$D$26,"ex_2013_14",'Reg IBOV'!$I$7:$I$26,"d_focus_pib3") | F8: % revisão / 1 p.p. | G8: Coeficiente contemporâneo
C9: Beta swap 360d | D9: =SUMIFS('Reg IBOV'!$J$7:$J$26,'Reg IBOV'!$D$7:$D$26,"ex_2013_14",'Reg IBOV'!$I$7:$I$26,"d_swap360_3") | E9: =SUMIFS('Reg IBOV'!$N$7:$N$26,'Reg IBOV'!$D$7:$D$26,"ex_2013_14",'Reg IBOV'!$I$7:$I$26,"d_swap360_3") | F9: % revisão / 1 p.p. | G9: Sinal positivo na amostra principal
C10: R² | D10: =SUMIFS('Reg IBOV'!$G$7:$G$26,'Reg IBOV'!$D$7:$D$26,"ex_2013_14",'Reg IBOV'!$I$7:$I$26,"d_focus_pib3") | F10: proporção | G10: Modelo com cinco variáveis
C11: Amostra | D11: ex_2013_14 | G11: 2013-2014 excluídos
C14: Revisão prevista de earnings em três meses (%) | M14: Matriz arquivada da análise original
C16: Focus Δ (p.p.) | D16: -3 | E16: -2 | F16: -1 | G16: 0 | H16: 1 | I16: 2 | J16: 3 | M16: focus_delta_pp | N16: swap_-3.00pp | O16: swap_-2.00pp | P16: swap_-1.00pp | Q16: swap_+0.00pp | R16: swap_+1.00pp | S16: swap_+2.00pp | T16: swap_+3.00pp
C17: -1 | D17: =$D$8*$C17+$D$9*D$16 | E17: =$D$8*$C17+$D$9*E$16 | F17: =$D$8*$C17+$D$9*F$16 | G17: =$D$8*$C17+$D$9*G$16 | H17: =$D$8*$C17+$D$9*H$16 | I17: =$D$8*$C17+$D$9*I$16 | J17: =$D$8*$C17+$D$9*J$16 | M17: -1 | N17: -11.197462 | O17: -9.465982 | P17: -7.7345022 | Q17: -6.0030225 | R17: -4.2715427 | S17: -2.5400629 | T17: -0.80858315
C18: -0.75 | D18: =$D$8*$C18+$D$9*D$16 | E18: =$D$8*$C18+$D$9*E$16 | F18: =$D$8*$C18+$D$9*F$16 | G18: =$D$8*$C18+$D$9*G$16 | H18: =$D$8*$C18+$D$9*H$16 | I18: =$D$8*$C18+$D$9*I$16 | J18: =$D$8*$C18+$D$9*J$16 | M18: -0.75 | N18: -9.6967062 | O18: -7.9652264 | P18: -6.2337466 | Q18: -4.5022669 | R18: -2.7707871 | S18: -1.0393073 | T18: 0.69217247
C19: -0.5 | D19: =$D$8*$C19+$D$9*D$16 | E19: =$D$8*$C19+$D$9*E$16 | F19: =$D$8*$C19+$D$9*F$16 | G19: =$D$8*$C19+$D$9*G$16 | H19: =$D$8*$C19+$D$9*H$16 | I19: =$D$8*$C19+$D$9*I$16 | J19: =$D$8*$C19+$D$9*J$16 | M19: -0.5 | N19: -8.1959506 | O19: -6.4644708 | P19: -4.732991 | Q19: -3.0015112 | R19: -1.2700315 | S19: 0.46144831 | T19: 2.1929281
C20: -0.25 | D20: =$D$8*$C20+$D$9*D$16 | E20: =$D$8*$C20+$D$9*E$16 | F20: =$D$8*$C20+$D$9*F$16 | G20: =$D$8*$C20+$D$9*G$16 | H20: =$D$8*$C20+$D$9*H$16 | I20: =$D$8*$C20+$D$9*I$16 | J20: =$D$8*$C20+$D$9*J$16 | M20: -0.25 | N20: -6.6951949 | O20: -4.9637152 | P20: -3.2322354 | Q20: -1.5007556 | R20: 0.23072416 | S20: 1.9622039 | T20: 3.6936837
C21: 0 | D21: =$D$8*$C21+$D$9*D$16 | E21: =$D$8*$C21+$D$9*E$16 | F21: =$D$8*$C21+$D$9*F$16 | G21: =$D$8*$C21+$D$9*G$16 | H21: =$D$8*$C21+$D$9*H$16 | I21: =$D$8*$C21+$D$9*I$16 | J21: =$D$8*$C21+$D$9*J$16 | M21: 0 | N21: -5.1944393 | O21: -3.4629595 | P21: -1.7314798 | Q21: 0 | R21: 1.7314798 | S21: 3.4629595 | T21: 5.1944393
C22: 0.25 | D22: =$D$8*$C22+$D$9*D$16 | E22: =$D$8*$C22+$D$9*E$16 | F22: =$D$8*$C22+$D$9*F$16 | G22: =$D$8*$C22+$D$9*G$16 | H22: =$D$8*$C22+$D$9*H$16 | I22: =$D$8*$C22+$D$9*I$16 | J22: =$D$8*$C22+$D$9*J$16 | M22: 0.25 | N22: -3.6936837 | O22: -1.9622039 | P22: -0.23072416 | Q22: 1.5007556 | R22: 3.2322354 | S22: 4.9637152 | T22: 6.6951949
C23: 0.5 | D23: =$D$8*$C23+$D$9*D$16 | E23: =$D$8*$C23+$D$9*E$16 | F23: =$D$8*$C23+$D$9*F$16 | G23: =$D$8*$C23+$D$9*G$16 | H23: =$D$8*$C23+$D$9*H$16 | I23: =$D$8*$C23+$D$9*I$16 | J23: =$D$8*$C23+$D$9*J$16 | M23: 0.5 | N23: -2.1929281 | O23: -0.46144831 | P23: 1.2700315 | Q23: 3.0015112 | R23: 4.732991 | S23: 6.4644708 | T23: 8.1959506
M25: Checagem | N25: Máximo entre três diferenças
C26: Interpretação | D26: A matriz combina mecanicamente os dois coeficientes. O beta positivo do swap não prova que juros maiores elevam lucros; o sinal perde significância em outras janelas e pode refletir composição, bancos e variáveis omitidas. | N26: =MAX(ABS(D17-N17),ABS(G20-Q20),ABS(J23-T23))

Sheet Inflacao
C2: Teste de inflação: realizado e expectativa Focus
C3: Comparação incremental contra o modelo-base com Focus PIB, BCOM e USD/BRL.
C6: Resultado principal - amostra ex_2013_14
C7: Candidato | D7: ΔR² | E7: Beta pad. | F7: p-valor HAC | G7: Leitura | H7: Uso no modelo final
C8: Focus IPCA | D8: =SUMIFS('Inflacao'!$K$15:$K$26,'Inflacao'!$C$15:$C$26,"ex_2013_14",'Inflacao'!$D$15:$D$26,"d_focus_ipca3") | E8: =SUMIFS('Inflacao'!$Q$15:$Q$26,'Inflacao'!$C$15:$C$26,"ex_2013_14",'Inflacao'!$D$15:$D$26,"d_focus_ipca3") | F8: =SUMIFS('Inflacao'!$P$15:$P$26,'Inflacao'!$C$15:$C$26,"ex_2013_14",'Inflacao'!$D$15:$D$26,"d_focus_ipca3") | G8: Boa associação na amostra principal | H8: Teste alternativo
C9: IPCA realizado 12m | D9: =SUMIFS('Inflacao'!$K$15:$K$26,'Inflacao'!$C$15:$C$26,"ex_2013_14",'Inflacao'!$D$15:$D$26,"d_ipca12_3_available") | E9: =SUMIFS('Inflacao'!$Q$15:$Q$26,'Inflacao'!$C$15:$C$26,"ex_2013_14",'Inflacao'!$D$15:$D$26,"d_ipca12_3_available") | F9: =SUMIFS('Inflacao'!$P$15:$P$26,'Inflacao'!$C$15:$C$26,"ex_2013_14",'Inflacao'!$D$15:$D$26,"d_ipca12_3_available") | G9: Maior ΔR² por pequena margem | H9: Selecionado
C10: Fluxo IPCA 3m | D10: =SUMIFS('Inflacao'!$K$15:$K$26,'Inflacao'!$C$15:$C$26,"ex_2013_14",'Inflacao'!$D$15:$D$26,"ipca3_flow_available") | E10: =SUMIFS('Inflacao'!$Q$15:$Q$26,'Inflacao'!$C$15:$C$26,"ex_2013_14",'Inflacao'!$D$15:$D$26,"ipca3_flow_available") | F10: =SUMIFS('Inflacao'!$P$15:$P$26,'Inflacao'!$C$15:$C$26,"ex_2013_14",'Inflacao'!$D$15:$D$26,"ipca3_flow_available") | G10: Mais fraco nesta especificação | H10: Não selecionado
C12: Resultados completos
C14: sample | D14: candidate | E14: start | F14: end | G14: n | H14: univariate_r2 | I14: base_r2 | J14: augmented_r2 | K14: delta_r2 | L14: delta_adj_r2 | M14: beta | N14: se_hac | O14: t_hac | P14: p_hac | Q14: beta_std
C15: full | D15: d_focus_ipca3 | E15: 39904 | F15: 46235 | G15: 209 | H15: 0.051087078 | I15: 0.19438588 | J15: 0.21666739 | K15: 0.022281511 | L15: 0.018639603 | M15: 4.3769951 | N15: 1.9620999 | O15: 2.2307708 | P15: 0.025696313 | Q15: 0.15618556
C16: full | D16: d_ipca12_3_available | E16: 39904 | F16: 46204 | G16: 208 | H16: 0.034625008 | I16: 0.19439343 | J16: 0.23067588 | K16: 0.036282442 | L16: 0.032828428 | M16: 2.3880205 | N16: 0.92459688 | O16: 2.5827694 | P16: 0.0098010809 | Q16: 0.19433206
C17: full | D17: ipca3_flow_available | E17: 39904 | F17: 46204 | G17: 208 | H17: 0.027085052 | I17: 0.19439343 | J17: 0.24320066 | K17: 0.048807227 | L17: 0.045537401 | M17: 3.4624943 | N17: 1.5639023 | O17: 2.2140093 | P17: 0.02682814 | Q17: 0.22296106
C18: ex_2013_14 | D18: d_focus_ipca3 | E18: 39904 | F18: 46235 | G18: 185 | H18: 0.13375353 | I18: 0.38223352 | J18: 0.45247777 | K18: 0.070244248 | L18: 0.067957937 | M18: 5.1884298 | N18: 1.9986835 | O18: 2.5959236 | P18: 0.0094337029 | Q18: 0.28068346
C19: ex_2013_14 | D19: d_ipca12_3_available | E19: 39904 | F19: 46204 | G19: 184 | H19: 0.071135062 | I19: 0.38220688 | J19: 0.46016632 | K19: 0.077959433 | L19: 0.075788648 | M19: 2.3279407 | N19: 0.89578869 | O19: 2.598761 | P19: 0.0093560885 | Q19: 0.28650397
C20: ex_2013_14 | D20: ipca3_flow_available | E20: 39904 | F20: 46204 | G20: 184 | H20: 0.022127964 | I20: 0.38220688 | J20: 0.4363602 | K20: 0.054153313 | L20: 0.05158576 | M20: 2.4609109 | N20: 1.3191149 | O20: 1.8655773 | P20: 0.062100525 | Q20: 0.23511163
C21: clean | D21: d_focus_ipca3 | E21: 39904 | F21: 46235 | G21: 161 | H21: 0.0066705469 | I21: 0.13793529 | J21: 0.15172719 | K21: 0.013791902 | L21: 0.0084950789 | M21: 1.6472374 | N21: 1.6108481 | O21: 1.0225901 | P21: 0.30650168 | Q21: 0.12354967
C22: clean | D22: d_ipca12_3_available | E22: 39904 | F22: 46204 | G22: 160 | H22: 0.0012211078 | I22: 0.13789605 | J22: 0.15205383 | K22: 0.01415778 | L22: 0.0088333392 | M22: 0.77310877 | N22: 0.78965519 | O22: 0.97904601 | P22: 0.32755724 | Q22: 0.12601101
C23: clean | D23: ipca3_flow_available | E23: 39904 | F23: 46204 | G23: 160 | H23: 0.0028244294 | I23: 0.13789605 | J23: 0.13890137 | K23: 0.0010053187 | L23: -0.0045720544 | M23: 0.24847881 | N23: 1.148877 | O23: 0.21627973 | P23: 0.82876971 | Q23: 0.032574407
C24: since_2015 | D24: d_focus_ipca3 | E24: 42005 | F24: 46235 | G24: 140 | H24: 0.15108406 | I24: 0.45191784 | J24: 0.52673088 | K24: 0.074813037 | L24: 0.072374476 | M24: 5.1843111 | N24: 2.0365908 | O24: 2.545583 | P24: 0.010909542 | Q24: 0.29091184
C25: since_2015 | D25: d_ipca12_3_available | E25: 42005 | F25: 46204 | G25: 139 | H25: 0.087532335 | I25: 0.45193942 | J25: 0.53098738 | K25: 0.079047957 | L25: 0.076685168 | M25: 2.2659847 | N25: 0.88703712 | O25: 2.5545546 | P25: 0.010632377 | Q25: 0.28928017
C26: since_2015 | D26: ipca3_flow_available | E26: 42005 | F26: 46204 | G26: 139 | H26: 0.023783784 | I26: 0.45193942 | J26: 0.50221027 | K26: 0.050270847 | L26: 0.047268567 | M26: 2.3066925 | N26: 1.4161533 | O26: 1.6288438 | P26: 0.1033461 | Q26: 0.22616223

Sheet Ex-Commodities
C2: IBOV versus IBOV ex-commodities
C3: Comparação da sensibilidade contemporânea ao Focus PIB. O agregado ex-commodities não apresenta beta maior.
C6: Amostra principal
C7: Métrica | D7: IBOV | E7: Ex-commodities | F7: Commodities | G7: Diferença ex-commod. - IBOV | H7: p da diferença
C8: Beta Focus | D8: =SUMIFS('Ex-Commodities'!$H$19:$H$24,'Ex-Commodities'!$C$19:$C$24,"ex_2013_14") | E8: =SUMIFS('Ex-Commodities'!$K$19:$K$24,'Ex-Commodities'!$C$19:$C$24,"ex_2013_14") | F8: =SUMIFS('Ex-Commodities'!$N$19:$N$24,'Ex-Commodities'!$C$19:$C$24,"ex_2013_14") | G8: =SUMIFS('Ex-Commodities'!$Q$19:$Q$24,'Ex-Commodities'!$C$19:$C$24,"ex_2013_14") | H8: =SUMIFS('Ex-Commodities'!$R$19:$R$24,'Ex-Commodities'!$C$19:$C$24,"ex_2013_14")
C9: Beta Focus padronizado | D9: =SUMIFS('Ex-Commodities'!$J$19:$J$24,'Ex-Commodities'!$C$19:$C$24,"ex_2013_14") | E9: =SUMIFS('Ex-Commodities'!$M$19:$M$24,'Ex-Commodities'!$C$19:$C$24,"ex_2013_14") | F9: =SUMIFS('Ex-Commodities'!$P$19:$P$24,'Ex-Commodities'!$C$19:$C$24,"ex_2013_14") | G9: =SUMIFS('Ex-Commodities'!$S$19:$S$24,'Ex-Commodities'!$C$19:$C$24,"ex_2013_14") | H9: =SUMIFS('Ex-Commodities'!$R$19:$R$24,'Ex-Commodities'!$C$19:$C$24,"ex_2013_14")
C10: R² | D10: =SUMIFS('Ex-Commodities'!$T$19:$T$24,'Ex-Commodities'!$C$19:$C$24,"ex_2013_14") | E10: =SUMIFS('Ex-Commodities'!$U$19:$U$24,'Ex-Commodities'!$C$19:$C$24,"ex_2013_14") | F10: =SUMIFS('Ex-Commodities'!$V$19:$V$24,'Ex-Commodities'!$C$19:$C$24,"ex_2013_14") | G10: =SUMIFS('Ex-Commodities'!$Q$19:$Q$24,'Ex-Commodities'!$C$19:$C$24,"ex_2013_14") | H10: =SUMIFS('Ex-Commodities'!$R$19:$R$24,'Ex-Commodities'!$C$19:$C$24,"ex_2013_14")
C12: Conclusão | D12: Na amostra ex_2013_14, o beta Focus do IBOV é 5,69; o ex-commodities é 2,03. A diferença é negativa e estatisticamente significativa.
C16: Resultados completos
C18: sample | D18: start | E18: end | F18: n | G18: corr_targets | H18: beta_focus_ibov | I18: p_focus_ibov | J18: beta_std_focus_ibov | K18: beta_focus_excommod | L18: p_focus_excommod | M18: beta_std_focus_excommod | N18: beta_focus_commodities | O18: p_focus_commodities | P18: beta_std_focus_commodities | Q18: beta_focus_difference | R18: p_focus_difference | S18: beta_std_focus_difference | T18: r2_ibov | U18: r2_excommod | V18: r2_commodities | W18: simple_beta_focus_ibov | X18: simple_beta_focus_excommod | Y18: simple_beta_focus_difference | Z18: simple_p_focus_difference
C19: full | D19: 40269 | E19: 46204 | F19: 196 | G19: 0.77273381 | H19: 5.6838321 | I19: 0 | J19: 0.58492857 | K19: 2.0245882 | L19: 0.0014139298 | M19: 0.42979377 | N19: 16.626687 | O19: 2.220446e-16 | P19: 0.63746331 | Q19: -3.659244 | R19: 7.2922024e-10 | S19: -0.54028435 | T19: 0.52953424 | U19: 0.32539094 | V19: 0.49793704 | W19: 5.8144083 | X19: 1.9599463 | Y19: -3.854462 | Z19: 2.2042355e-09
C20: ex_2013_14 | D20: 40269 | E20: 46204 | F20: 172 | G20: 0.7844963 | H20: 5.6862799 | I20: 0 | J20: 0.58372253 | K20: 2.0316214 | L20: 0.0015772984 | M20: 0.43059679 | N20: 16.77568 | O20: 4.4408921e-16 | P20: 0.64422181 | Q20: -3.6546584 | R20: 1.321248e-09 | S20: -0.54454524 | T20: 0.53074521 | U20: 0.33632929 | V20: 0.49961302 | W20: 5.8148233 | X20: 2.0074505 | Y20: -3.8073729 | Z20: 2.2373849e-09
C21: ex_2020_21 | D21: 40269 | E21: 46204 | F21: 172 | G21: 0.64760949 | H21: 2.97663 | I21: 3.0606539e-05 | J21: 0.29643849 | K21: 0.50906147 | L21: 0.44433621 | M21: 0.11300114 | N21: 11.303102 | O21: 0.00062052781 | P21: 0.35441495 | Q21: -2.4675685 | R21: 0.00028699834 | S21: -0.31204424 | T21: 0.17326481 | U21: 0.099670595 | V21: 0.16525826 | W21: 2.5352897 | X21: 0.32743712 | Y21: -2.2078526 | Z21: 0.009434023
C22: clean | D22: 40269 | E22: 46204 | F22: 148 | G22: 0.67186854 | H22: 2.8658246 | I22: 7.3195393e-05 | J22: 0.28039642 | K22: 0.50961196 | L22: 0.45944161 | M22: 0.11264326 | N22: 11.168532 | O22: 0.0011600299 | P22: 0.34430372 | Q22: -2.3562127 | R22: 0.00037619337 | S22: -0.29733856 | T22: 0.16189714 | U22: 0.12049004 | V22: 0.15527248 | W22: 2.3728469 | X22: 0.33233882 | Y22: -2.0405081 | Z22: 0.016598513
C23: since_2015 | D23: 42005 | E23: 46204 | F23: 139 | G23: 0.78369738 | H23: 5.8920577 | I23: 0 | J23: 0.61634097 | K23: 2.3324491 | L23: 0.00047484391 | M23: 0.50656073 | N23: 17.363721 | O23: 0 | P23: 0.66560903 | Q23: -3.5596085 | R23: 1.5808829e-08 | S23: -0.53910681 | T23: 0.57071757 | U23: 0.37196196 | V23: 0.52395601 | W23: 6.0517688 | X23: 2.1637738 | Y23: -3.8879951 | Z23: 8.309966e-10
C24: since_2022 | D24: 44562 | E24: 46204 | F24: 55 | G24: 0.67015668 | H24: 2.1196906 | I24: 0.30324555 | J24: 0.12331172 | K24: 1.0779143 | L24: 0.23086256 | M24: 0.16545087 | N24: 3.2410841 | O24: 0.41723308 | P24: 0.086284 | Q24: -1.0417764 | R24: 0.47132578 | S24: -0.076014163 | T24: 0.4510281 | U24: 0.38146338 | V24: 0.36019949 | W24: 2.2330527 | X24: 1.3714856 | Y24: -0.86156714 | Z24: 0.71055441

Sheet Energia
C2: Energia, Petrobras e Brent
C3: Decomposição da liderança setorial. A série agregada de Energia é fortemente dominada por Petrobras.
C6: Concentração e correlação
C7: Métrica | D7: Valor | E7: Unidade | F7: Amostra | G7: Leitura | H7: Fonte
C8: Correlação revisions Energia-Petrobras | D8: 0.995009 | E8: correlação | F8: primary | G8: Movimentos quase idênticos | H8: Resumo Energia
C9: Meses Energy = Petrobras | D9: 106 | E9: meses | F9: 225 meses | G9: 47,1% do histórico | H9: Resumo Energia
C10: Participação mediana Petrobras | D10: 0.9212272 | E10: % do setor | F10: desde 2023 | G10: 92,1% do agregado | H10: Resumo Energia
C11: R² univariado Energia-Petrobras | D11: 0.99004291 | E11: proporção | F11: primary | G11: Quase toda variação comum | H11: Resumo Energia
C14: Modelo com Brent - principais amostras
C15: Target | D15: Amostra | E15: n | F15: R² | G15: Focus beta | H15: Focus p | I15: Brent beta | J15: Brent beta pad.
C16: Energy reported | D16: primary | E16: =SUMIFS('Reg Energia'!$H$7:$H$74,'Reg Energia'!$C$7:$C$74,$C16,'Reg Energia'!$D$7:$D$74,$D16,'Reg Energia'!$E$7:$E$74,"Brent") | F16: =SUMIFS('Reg Energia'!$I$7:$I$74,'Reg Energia'!$C$7:$C$74,$C16,'Reg Energia'!$D$7:$D$74,$D16,'Reg Energia'!$E$7:$E$74,"Brent") | G16: =SUMIFS('Reg Energia'!$L$7:$L$74,'Reg Energia'!$C$7:$C$74,$C16,'Reg Energia'!$D$7:$D$74,$D16,'Reg Energia'!$E$7:$E$74,"Brent") | H16: =SUMIFS('Reg Energia'!$O$7:$O$74,'Reg Energia'!$C$7:$C$74,$C16,'Reg Energia'!$D$7:$D$74,$D16,'Reg Energia'!$E$7:$E$74,"Brent") | I16: =SUMIFS('Reg Energia'!$AF$7:$AF$74,'Reg Energia'!$C$7:$C$74,$C16,'Reg Energia'!$D$7:$D$74,$D16,'Reg Energia'!$E$7:$E$74,"Brent") | J16: =SUMIFS('Reg Energia'!$AG$7:$AG$74,'Reg Energia'!$C$7:$C$74,$C16,'Reg Energia'!$D$7:$D$74,$D16,'Reg Energia'!$E$7:$E$74,"Brent")
C17: Petrobras | D17: primary | E17: =SUMIFS('Reg Energia'!$H$7:$H$74,'Reg Energia'!$C$7:$C$74,$C17,'Reg Energia'!$D$7:$D$74,$D17,'Reg Energia'!$E$7:$E$74,"Brent") | F17: =SUMIFS('Reg Energia'!$I$7:$I$74,'Reg Energia'!$C$7:$C$74,$C17,'Reg Energia'!$D$7:$D$74,$D17,'Reg Energia'!$E$7:$E$74,"Brent") | G17: =SUMIFS('Reg Energia'!$L$7:$L$74,'Reg Energia'!$C$7:$C$74,$C17,'Reg Energia'!$D$7:$D$74,$D17,'Reg Energia'!$E$7:$E$74,"Brent") | H17: =SUMIFS('Reg Energia'!$O$7:$O$74,'Reg Energia'!$C$7:$C$74,$C17,'Reg Energia'!$D$7:$D$74,$D17,'Reg Energia'!$E$7:$E$74,"Brent") | I17: =SUMIFS('Reg Energia'!$AF$7:$AF$74,'Reg Energia'!$C$7:$C$74,$C17,'Reg Energia'!$D$7:$D$74,$D17,'Reg Energia'!$E$7:$E$74,"Brent") | J17: =SUMIFS('Reg Energia'!$AG$7:$AG$74,'Reg Energia'!$C$7:$C$74,$C17,'Reg Energia'!$D$7:$D$74,$D17,'Reg Energia'!$E$7:$E$74,"Brent")
C18: Ex-Petrobras dynamic | D18: primary | E18: =SUMIFS('Reg Energia'!$H$7:$H$74,'Reg Energia'!$C$7:$C$74,$C18,'Reg Energia'!$D$7:$D$74,$D18,'Reg Energia'!$E$7:$E$74,"Brent") | F18: =SUMIFS('Reg Energia'!$I$7:$I$74,'Reg Energia'!$C$7:$C$74,$C18,'Reg Energia'!$D$7:$D$74,$D18,'Reg Energia'!$E$7:$E$74,"Brent") | G18: =SUMIFS('Reg Energia'!$L$7:$L$74,'Reg Energia'!$C$7:$C$74,$C18,'Reg Energia'!$D$7:$D$74,$D18,'Reg Energia'!$E$7:$E$74,"Brent") | H18: =SUMIFS('Reg Energia'!$O$7:$O$74,'Reg Energia'!$C$7:$C$74,$C18,'Reg Energia'!$D$7:$D$74,$D18,'Reg Energia'!$E$7:$E$74,"Brent") | I18: =SUMIFS('Reg Energia'!$AF$7:$AF$74,'Reg Energia'!$C$7:$C$74,$C18,'Reg Energia'!$D$7:$D$74,$D18,'Reg Energia'!$E$7:$E$74,"Brent") | J18: =SUMIFS('Reg Energia'!$AG$7:$AG$74,'Reg Energia'!$C$7:$C$74,$C18,'Reg Energia'!$D$7:$D$74,$D18,'Reg Energia'!$E$7:$E$74,"Brent")
C19: Energy reported | D19: audit_clean | E19: =SUMIFS('Reg Energia'!$H$7:$H$74,'Reg Energia'!$C$7:$C$74,$C19,'Reg Energia'!$D$7:$D$74,$D19,'Reg Energia'!$E$7:$E$74,"Brent") | F19: =SUMIFS('Reg Energia'!$I$7:$I$74,'Reg Energia'!$C$7:$C$74,$C19,'Reg Energia'!$D$7:$D$74,$D19,'Reg Energia'!$E$7:$E$74,"Brent") | G19: =SUMIFS('Reg Energia'!$L$7:$L$74,'Reg Energia'!$C$7:$C$74,$C19,'Reg Energia'!$D$7:$D$74,$D19,'Reg Energia'!$E$7:$E$74,"Brent") | H19: =SUMIFS('Reg Energia'!$O$7:$O$74,'Reg Energia'!$C$7:$C$74,$C19,'Reg Energia'!$D$7:$D$74,$D19,'Reg Energia'!$E$7:$E$74,"Brent") | I19: =SUMIFS('Reg Energia'!$AF$7:$AF$74,'Reg Energia'!$C$7:$C$74,$C19,'Reg Energia'!$D$7:$D$74,$D19,'Reg Energia'!$E$7:$E$74,"Brent") | J19: =SUMIFS('Reg Energia'!$AG$7:$AG$74,'Reg Energia'!$C$7:$C$74,$C19,'Reg Energia'!$D$7:$D$74,$D19,'Reg Energia'!$E$7:$E$74,"Brent")
C20: Petrobras | D20: audit_clean | E20: =SUMIFS('Reg Energia'!$H$7:$H$74,'Reg Energia'!$C$7:$C$74,$C20,'Reg Energia'!$D$7:$D$74,$D20,'Reg Energia'!$E$7:$E$74,"Brent") | F20: =SUMIFS('Reg Energia'!$I$7:$I$74,'Reg Energia'!$C$7:$C$74,$C20,'Reg Energia'!$D$7:$D$74,$D20,'Reg Energia'!$E$7:$E$74,"Brent") | G20: =SUMIFS('Reg Energia'!$L$7:$L$74,'Reg Energia'!$C$7:$C$74,$C20,'Reg Energia'!$D$7:$D$74,$D20,'Reg Energia'!$E$7:$E$74,"Brent") | H20: =SUMIFS('Reg Energia'!$O$7:$O$74,'Reg Energia'!$C$7:$C$74,$C20,'Reg Energia'!$D$7:$D$74,$D20,'Reg Energia'!$E$7:$E$74,"Brent") | I20: =SUMIFS('Reg Energia'!$AF$7:$AF$74,'Reg Energia'!$C$7:$C$74,$C20,'Reg Energia'!$D$7:$D$74,$D20,'Reg Energia'!$E$7:$E$74,"Brent") | J20: =SUMIFS('Reg Energia'!$AG$7:$AG$74,'Reg Energia'!$C$7:$C$74,$C20,'Reg Energia'!$D$7:$D$74,$D20,'Reg Energia'!$E$7:$E$74,"Brent")
C21: Energy reported | D21: since_2022_ex_seams | E21: =SUMIFS('Reg Energia'!$H$7:$H$74,'Reg Energia'!$C$7:$C$74,$C21,'Reg Energia'!$D$7:$D$74,$D21,'Reg Energia'!$E$7:$E$74,"Brent") | F21: =SUMIFS('Reg Energia'!$I$7:$I$74,'Reg Energia'!$C$7:$C$74,$C21,'Reg Energia'!$D$7:$D$74,$D21,'Reg Energia'!$E$7:$E$74,"Brent") | G21: =SUMIFS('Reg Energia'!$L$7:$L$74,'Reg Energia'!$C$7:$C$74,$C21,'Reg Energia'!$D$7:$D$74,$D21,'Reg Energia'!$E$7:$E$74,"Brent") | H21: =SUMIFS('Reg Energia'!$O$7:$O$74,'Reg Energia'!$C$7:$C$74,$C21,'Reg Energia'!$D$7:$D$74,$D21,'Reg Energia'!$E$7:$E$74,"Brent") | I21: =SUMIFS('Reg Energia'!$AF$7:$AF$74,'Reg Energia'!$C$7:$C$74,$C21,'Reg Energia'!$D$7:$D$74,$D21,'Reg Energia'!$E$7:$E$74,"Brent") | J21: =SUMIFS('Reg Energia'!$AG$7:$AG$74,'Reg Energia'!$C$7:$C$74,$C21,'Reg Energia'!$D$7:$D$74,$D21,'Reg Energia'!$E$7:$E$74,"Brent")
C22: Petrobras | D22: since_2022_ex_seams | E22: =SUMIFS('Reg Energia'!$H$7:$H$74,'Reg Energia'!$C$7:$C$74,$C22,'Reg Energia'!$D$7:$D$74,$D22,'Reg Energia'!$E$7:$E$74,"Brent") | F22: =SUMIFS('Reg Energia'!$I$7:$I$74,'Reg Energia'!$C$7:$C$74,$C22,'Reg Energia'!$D$7:$D$74,$D22,'Reg Energia'!$E$7:$E$74,"Brent") | G22: =SUMIFS('Reg Energia'!$L$7:$L$74,'Reg Energia'!$C$7:$C$74,$C22,'Reg Energia'!$D$7:$D$74,$D22,'Reg Energia'!$E$7:$E$74,"Brent") | H22: =SUMIFS('Reg Energia'!$O$7:$O$74,'Reg Energia'!$C$7:$C$74,$C22,'Reg Energia'!$D$7:$D$74,$D22,'Reg Energia'!$E$7:$E$74,"Brent") | I22: =SUMIFS('Reg Energia'!$AF$7:$AF$74,'Reg Energia'!$C$7:$C$74,$C22,'Reg Energia'!$D$7:$D$74,$D22,'Reg Energia'!$E$7:$E$74,"Brent") | J22: =SUMIFS('Reg Energia'!$AG$7:$AG$74,'Reg Energia'!$C$7:$C$74,$C22,'Reg Energia'!$D$7:$D$74,$D22,'Reg Energia'!$E$7:$E$74,"Brent")
C24: Conclusão | D24: A sensibilidade de Energia ao Focus no histórico vem quase integralmente de Petrobras. Desde 2022, Focus deixa de ser significativo, enquanto Brent ganha força explicativa para Energia e Petrobras.

Sheet Earnings 12M Fwd
C2: Earnings 12 meses forward por setor
C3: BEst Net Income agregado, em BRL. Frequência mensal, janeiro de 2008 a setembro de 2026.
C6: month | D6: date | E6: source_file | F6: IBOV | G6: Communication Services | H6: Consumer Discretionary | I6: Consumer Staples | J6: Energy | K6: Financials | L6: Health Care | M6: Industrials | N6: Information Technology | O6: Materials | P6: Real Estate | Q6: Utilities | R6: Not Classified
C7: 39448 | D7: 39478 | E7: grid_20qvjmd3.xlsx | F7: 9959.8781 | G7: 730.2102 | H7: 310.7799 | I7: 1538.5402 | J7: 29432.834 | K7: 7614.5858 | M7: 659.91204 | O7: 13618.164 | P7: 0 | Q7: 1217.2182 | R7: 1487.481
C8: 39479 | D8: 39507 | E8: grid_20qvjmd3.xlsx | F8: 10289.607 | G8: 799.94292 | H8: 322.53156 | I8: 1573.9043 | J8: 29645.202 | K8: 7762.6191 | M8: 623.17107 | O8: 14526.618 | P8: 0 | Q8: 1242.4285 | R8: 1474.0469
C9: 39508 | D9: 39538 | E9: grid_20qvjmd3.xlsx | F9: 10303.867 | G9: 747.09409 | H9: 295.13034 | I9: 1515.5028 | J9: 30769.554 | K9: 7843.4509 | M9: 615.38921 | O9: 14775.051 | P9: 0 | Q9: 1312.0471 | R9: 1479.4428
C10: 39539 | D10: 39568 | E10: grid_20qvjmd3.xlsx | F10: 10682.523 | G10: 711.0442 | H10: 300.91403 | I10: 1451.0769 | J10: 30957.47 | K10: 7909.4795 | M10: 601.75089 | O10: 15217.403 | P10: 0 | Q10: 1381.0617 | R10: 1445.746
C11: 39569 | D11: 39598 | E11: grid_20qvjmd3.xlsx | F11: 12096.372 | G11: 728.05057 | H11: 316.88361 | I11: 1504.6715 | J11: 32324.668 | K11: 7871.6928 | M11: 560.65459 | O11: 16212.108 | P11: 15.079452 | Q11: 1352.8194 | R11: 1468.2037
C12: 39600 | D12: 39629 | E12: grid_20qvjmd3.xlsx | F12: 12518.425 | G12: 698.83604 | H12: 312.29658 | I12: 1526.8364 | J12: 32989.739 | K12: 7885.199 | M12: 550.09937 | O12: 16313.358 | P12: 32.887671 | Q12: 1312.6731 | R12: 1429.9287
C13: 39630 | D13: 39660 | E13: grid_20qvjmd3.xlsx | F13: 11614.211 | G13: 737.06608 | H13: 294.20667 | I13: 1419.8973 | J13: 34314.985 | K13: 7863.2461 | M13: 526.79196 | O13: 16167.317 | P13: 33.142466 | Q13: 1358.7449 | R13: 1440.5456
C14: 39661 | D14: 39689 | E14: grid_20qvjmd3.xlsx | F14: 12104.025 | G14: 704.56496 | H14: 302.12598 | I14: 1507.0539 | J14: 34896.378 | K14: 7875.0501 | M14: 562.0758 | O14: 17087.953 | P14: 33.380822 | Q14: 1408.5327 | R14: 1464.0215
C15: 39692 | D15: 39721 | E15: grid_20qvjmd3.xlsx | F15: 14266.987 | G15: 648.71691 | H15: 363.48552 | I15: 1740.5418 | J15: 36268.299 | K15: 6828.52 | M15: 570.98461 | O15: 19240.008 | Q15: 1547.7116 | R15: 1549.4413
C16: 39722 | D16: 39752 | E16: grid_20qvjmd3.xlsx | F16: 13115.579 | G16: 651.81029 | H16: 372.63442 | I16: 1602.3352 | J16: 34382.252 | K16: 6519.0678 | M16: 615.47934 | O16: 19187.929 | Q16: 1649.2131 | R16: 1504.1739
C17: 39753 | D17: 39780 | E17: grid_20qvjmd3.xlsx | F17: 11850.102 | G17: 607.49416 | H17: 374.84868 | I17: 1660.5916 | J17: 33491.21 | K17: 6650.3507 | M17: 564.2881 | O17: 18370.268 | Q17: 1679.6568 | R17: 1435.6145
C18: 39783 | D18: 39813 | E18: grid_20qvjmd3.xlsx | F18: 11084.465 | G18: 670.9664 | H18: 379.83185 | I18: 1698.7055 | J18: 29096.401 | K18: 6484.0951 | M18: 578.34412 | O18: 15653.676 | Q18: 1771.2051 | R18: 1351.3939
C19: 39814 | D19: 39843 | E19: grid_20qvjmd3.xlsx | F19: 11033.739 | G19: 640.17612 | H19: 347.01657 | I19: 1563.1346 | J19: 26792.882 | K19: 5406.3233 | M19: 540.54578 | O19: 13243.352 | Q19: 1779.3234 | R19: 1135.9492
C20: 39845 | D20: 39871 | E20: grid_20qvjmd3.xlsx | F20: 11190.357 | G20: 645.2784 | H20: 328.20651 | I20: 1504.9584 | J20: 27042.788 | K20: 5467.7979 | M20: 525.43514 | O20: 12737.026 | Q20: 1765.0099 | R20: 1192.0434
C21: 39873 | D21: 39903 | E21: grid_20qvjmd3.xlsx | F21: 9959.6275 | G21: 630.3768 | H21: 340.80954 | I21: 1622.1641 | J21: 24508.116 | K21: 5928.7117 | M21: 546.01697 | O21: 9925.1371 | Q21: 1873.3138 | R21: 820.10453
C22: 39904 | D22: 39933 | E22: grid_20qvjmd3.xlsx | F22: 9074.784 | G22: 629.58648 | H22: 333.6687 | I22: 1658.3479 | J22: 23604.085 | K22: 6085.9008 | M22: 525.99031 | O22: 9126.5962 | Q22: 1866.2613 | R22: 727.80768
C23: 39934 | D23: 39962 | E23: grid_20qvjmd3.xlsx | F23: 9195.7719 | G23: 638.47895 | H23: 339.31323 | I23: 1772.2349 | J23: 25104.484 | K23: 6117.9407 | M23: 493.3957 | O23: 8106.9492 | Q23: 1833.8755 | R23: 660.49468
C24: 39965 | D24: 39994 | E24: grid_20qvjmd3.xlsx | F24: 8893.8981 | G24: 664.9811 | H24: 352.41646 | I24: 1886.2962 | J24: 25090.749 | K24: 6197.1161 | M24: 451.67579 | O24: 7502.1873 | Q24: 1790.4215 | R24: 680.26612
C25: 39995 | D25: 40025 | E25: grid_20qvjmd3.xlsx | F25: 8563.7339 | G25: 662.31383 | H25: 353.15989 | I25: 1900.1433 | J25: 25347.72 | K25: 6435.6718 | M25: 443.422 | O25: 7340.7243 | Q25: 1799.9765 | R25: 615.99822
C26: 40026 | D26: 40056 | E26: grid_20qvjmd3.xlsx | F26: 8388.6174 | G26: 670.24742 | H26: 378.10991 | I26: 1999.4413 | J26: 25339.542 | K26: 6759.6343 | M26: 443.33358 | O26: 7170.4337 | Q26: 1775.9242 | R26: 596.93812
... C42: 40513 | D42: 40543 | E42: grid_20qvjmd3.xlsx | F42: 12597.863 | G42: 1081.8309 | H42: 796.76356 | I42: 2149.2761 | J42: 28108.46 | K42: 8337.9013 | M42: 490.4191 | O42: 20834.845 | Q42: 1741.8561 | R42: 1154.9933
C43: 40544 | D43: 40574 | E43: grid_u4lflnxf.xlsx | F43: 13177.516 | G43: 1126.5085 | H43: 813.82382 | I43: 1953.6148 | J43: 27471.717 | K43: 8650.6158 | L43: 554.65455 | M43: 495.63938 | O43: 21251.872 | Q43: 1773.2684 | R43: 1189.0901
C44: 40575 | D44: 40602 | E44: grid_u4lflnxf.xlsx | F44: 13431.267 | G44: 1141.2273 | H44: 825.20486 | I44: 1968.4379 | J44: 26929.303 | K44: 8864.1093 | L44: 554.50537 | M44: 496.29057 | O44: 21797.318 | Q44: 1900.2079 | R44: 1206.2501
C45: 40603 | D45: 40633 | E45: grid_u4lflnxf.xlsx | F45: 13213.049 | G45: 1183.8905 | H45: 816.07302 | I45: 2026.2886 | J45: 27197.922 | K45: 8887.4956 | L45: 549.84882 | M45: 503.51999 | O45: 21365.347 | Q45: 1844.7872 | R45: 1196.9227
C46: 40634 | D46: 40662 | E46: grid_u4lflnxf.xlsx | F46: 13174.745 | G46: 1236.4062 | H46: 771.07094 | I46: 2106.0355 | J46: 27678.808 | K46: 8780.3506 | L46: 561.7208 | M46: 537.49559 | O46: 22602.416 | Q46: 1807.6412 | R46: 1192.0052
C47: 40664 | D47: 40694 | E47: grid_u4lflnxf.xlsx | F47: 12498.057 | G47: 1319.9249 | H47: 790.07586 | I47: 2435.7214 | J47: 26793.304 | K47: 8103.5484 | L47: 553.04753 | M47: 520.88829 | O47: 21850.633 | Q47: 1752.098 | R47: 1139.2069
C48: 40695 | D48: 40724 | E48: grid_u4lflnxf.xlsx | F48: 13424.289 | G48: 2389.7871 | H48: 787.44199 | I48: 2510.4604 | J48: 28449.118 | K48: 9452.6372 | L48: 525.4246 | M48: 515.06246 | O48: 22756.224 | Q48: 1795.0594 | R48: 921.37192
C49: 40725 | D49: 40753 | E49: grid_u4lflnxf.xlsx | F49: 14082.429 | G49: 2929.4215 | H49: 786.70871 | I49: 2490.1949 | J49: 29939.869 | K49: 9316.5436 | L49: 545.86818 | M49: 494.3744 | O49: 23901.656 | Q49: 1759.9509 | R49: 847.72284
C50: 40756 | D50: 40786 | E50: grid_u4lflnxf.xlsx | F50: 13480.664 | G50: 2994.2119 | H50: 768.66495 | I50: 2898.598 | J50: 31037.45 | K50: 9078.7949 | L50: 438.47068 | M50: 491.55847 | O50: 22698.704 | Q50: 1807.9884 | R50: 826.00672
C51: 40787 | D51: 40816 | E51: grid_u4lflnxf.xlsx | F51: 13359.183 | G51: 2948.7514 | H51: 762.29801 | I51: 3004.3039 | J51: 28543.005 | K51: 9527.1469 | L51: 403.33234 | M51: 472.16287 | O51: 21510.873 | P51: 460.51956 | Q51: 1855.7692 | R51: 872.95498
C52: 40817 | D52: 40847 | E52: grid_u4lflnxf.xlsx | F52: 12887.068 | G52: 2977.0702 | H52: 752.13183 | I52: 2899.0166 | J52: 26850.87 | K52: 9437.5241 | L52: 383.61716 | M52: 466.67072 | O52: 20890.485 | P52: 475.93034 | Q52: 1821.7665 | R52: 876.13191
C53: 40848 | D53: 40877 | E53: grid_u4lflnxf.xlsx | F53: 13114.066 | G53: 3089.3269 | H53: 766.41211 | I53: 2909.4206 | J53: 27913.406 | K53: 9473.3468 | L53: 292.51458 | M53: 498.0255 | O53: 20853.436 | P53: 485.39128 | Q53: 1773.6944 | R53: 935.79669
C54: 40878 | D54: 40907 | E54: grid_u4lflnxf.xlsx | F54: 12652.236 | G54: 3118.0787 | H54: 825.73919 | I54: 3072.8995 | J54: 27142.859 | K54: 9585.3142 | L54: 293.79917 | M54: 537.61278 | O54: 19816.883 | P54: 485.74471 | Q54: 1776.3335 | R54: 947.72285
C55: 40909 | D55: 40939 | E55: grid_u4lflnxf.xlsx | F55: 11926.745 | G55: 2908.9099 | H55: 732.43135 | I55: 3225.8924 | J55: 26838.628 | K55: 9646.2866 | L55: 310.00596 | M55: 516.6193 | O55: 19404.559 | P55: 486.68823 | Q55: 1805.4298 | R55: 935.73725
C56: 40940 | D56: 40968 | E56: grid_u4lflnxf.xlsx | F56: 10690.21 | G56: 2889.3263 | H56: 702.84712 | I56: 3167.959 | J56: 24956.172 | K56: 9593.8834 | L56: 319.11295 | M56: 521.61935 | O56: 16928.694 | P56: 495.14552 | Q56: 1838.0278 | R56: 965.98851
C57: 40969 | D57: 40998 | E57: grid_u4lflnxf.xlsx | F57: 10556.646 | G57: 2931.2008 | H57: 702.39977 | I57: 3372.5556 | J57: 25459.278 | K57: 9669.8944 | L57: 321.61388 | M57: 568.5961 | O57: 16516.665 | P57: 508.2415 | Q57: 1820.224 | R57: 989.99782
C58: 41000 | D58: 41029 | E58: grid_u4lflnxf.xlsx | F58: 10530.904 | G58: 2191.1385 | H58: 677.60072 | I58: 3424.3011 | J58: 25130.939 | K58: 9292.8961 | L58: 331.53168 | M58: 605.54558 | O58: 16770.347 | P58: 499.77018 | Q58: 1928.7015 | R58: 980.56303
...

Sheet Earnings Base 100
C2: Earnings 12 meses forward em base 100
C3: Janeiro de 2020 = 100. Séries setoriais e IBOV calculadas a partir do consolidado mensal.
C6: month | D6: date | E6: source_file | F6: IBOV | G6: Communication Services | H6: Consumer Discretionary | I6: Consumer Staples | J6: Energy | K6: Financials | L6: Health Care | M6: Industrials | N6: Information Technology | O6: Materials | P6: Real Estate | Q6: Utilities
C7: 39448 | D7: 39478 | E7: grid_20qvjmd3.xlsx | F7: 70.762078 | G7: 17.120159 | H7: 29.237501 | I7: 22.558884 | J7: 80.216936 | K7: 41.959597 | M7: 47.721233 | O7: 57.966827 | P7: 0 | Q7: 44.448037
C8: 39479 | D8: 39507 | E8: grid_20qvjmd3.xlsx | F8: 73.10471 | G8: 18.755079 | H8: 30.343071 | I8: 23.077412 | J8: 80.795727 | K8: 42.775323 | M8: 45.064327 | O8: 61.833736 | P8: 0 | Q8: 45.368616
C9: 39508 | D9: 39538 | E9: grid_20qvjmd3.xlsx | F9: 73.206024 | G9: 17.516011 | H9: 27.765224 | I9: 22.221098 | J9: 83.860062 | K9: 43.220741 | M9: 44.501586 | O9: 62.891211 | P9: 0 | Q9: 47.910815
C10: 39539 | D10: 39568 | E10: grid_20qvjmd3.xlsx | F10: 75.896261 | G10: 16.670802 | H10: 28.309341 | I10: 21.276451 | J10: 84.372212 | K10: 43.584587 | M10: 43.515337 | O10: 64.774119 | P10: 0 | Q10: 50.430959
C11: 39569 | D11: 39598 | E11: grid_20qvjmd3.xlsx | F11: 85.941257 | G11: 17.069525 | H11: 29.811724 | I11: 22.062284 | J11: 88.098408 | K11: 43.376366 | M11: 40.543477 | O11: 69.008165 | P11: 2.5069078 | Q11: 49.399658
C12: 39600 | D12: 39629 | E12: grid_20qvjmd3.xlsx | F12: 88.939823 | G12: 16.384575 | H12: 29.380186 | I12: 22.387278 | J12: 89.911008 | K12: 43.450791 | M12: 39.780181 | O12: 69.439144 | P12: 5.467464 | Q12: 47.933674
C13: 39630 | D13: 39660 | E13: grid_20qvjmd3.xlsx | F13: 82.515638 | G13: 17.280899 | H13: 27.678327 | I13: 20.819279 | J13: 93.522863 | K13: 43.329821 | M13: 38.094717 | O13: 68.817506 | P13: 5.5098227 | Q13: 49.616034
C14: 39661 | D14: 39689 | E14: grid_20qvjmd3.xlsx | F14: 85.995624 | G14: 16.518893 | H14: 28.423359 | I14: 22.097217 | J14: 95.107405 | K14: 43.394866 | M14: 40.646251 | O14: 72.73627 | P14: 5.5494486 | Q14: 51.434089
C15: 39692 | D15: 39721 | E15: grid_20qvjmd3.xlsx | F15: 101.36286 | G15: 15.209506 | H15: 34.195931 | I15: 25.520739 | J15: 98.84647 | K15: 37.628041 | M15: 41.290488 | O15: 81.896665 | Q15: 56.516357
C16: 39722 | D16: 39752 | E16: grid_20qvjmd3.xlsx | F16: 93.182427 | G16: 15.282032 | H16: 35.056639 | I16: 23.49428 | J16: 93.706193 | K16: 35.922829 | M16: 44.508103 | O16: 81.674988 | Q16: 60.222794
C17: 39753 | D17: 39780 | E17: grid_20qvjmd3.xlsx | F17: 84.191574 | G17: 14.243017 | H17: 35.264952 | I17: 24.348467 | J17: 91.277729 | K17: 36.646253 | M17: 40.806233 | O17: 78.194548 | Q17: 61.33448
C18: 39783 | D18: 39813 | E18: grid_20qvjmd3.xlsx | F18: 78.751945 | G18: 15.731157 | H18: 35.733759 | I18: 24.907312 | J18: 79.300012 | K18: 35.730114 | M18: 41.822687 | O18: 66.631154 | Q18: 64.677465
C19: 39814 | D19: 39843 | E19: grid_20qvjmd3.xlsx | F19: 78.391552 | G19: 15.009263 | H19: 32.646568 | I19: 22.919501 | J19: 73.021947 | K19: 29.791135 | M19: 39.089318 | O19: 56.371411 | Q19: 64.973911
C20: 39845 | D20: 39871 | E20: grid_20qvjmd3.xlsx | F20: 79.504281 | G20: 15.128888 | H20: 30.876959 | I20: 22.066491 | J20: 73.703046 | K20: 30.129885 | M20: 37.996599 | O20: 54.216192 | Q20: 64.451238
C21: 39873 | D21: 39903 | E21: grid_20qvjmd3.xlsx | F21: 70.760297 | G21: 14.779513 | H21: 32.062623 | I21: 23.785023 | J21: 66.794992 | K21: 32.669716 | M21: 39.484964 | O21: 42.247158 | Q21: 68.406075
C22: 39904 | D22: 39933 | E22: grid_20qvjmd3.xlsx | F22: 64.473738 | G22: 14.760983 | H22: 31.390829 | I22: 24.315568 | J22: 64.331126 | K22: 33.535894 | M22: 38.036746 | O22: 38.848103 | Q22: 68.148542
C23: 39934 | D23: 39962 | E23: grid_20qvjmd3.xlsx | F23: 65.333322 | G23: 14.969472 | H23: 31.921854 | I23: 25.985439 | J23: 68.420348 | K23: 33.712448 | M23: 35.679681 | O23: 34.507892 | Q23: 66.96594
C24: 39965 | D24: 39994 | E24: grid_20qvjmd3.xlsx | F24: 63.188596 | G24: 15.590829 | H24: 33.154578 | I24: 27.657865 | J24: 68.382916 | K24: 34.148738 | M24: 32.662725 | O24: 31.933674 | Q24: 65.37917
C25: 39995 | D25: 40025 | E25: grid_20qvjmd3.xlsx | F25: 60.842874 | G25: 15.528293 | H25: 33.224518 | I25: 27.860899 | J25: 69.08327 | K25: 35.463281 | M25: 32.065856 | O25: 31.246393 | Q25: 65.728082
C26: 40026 | D26: 40056 | E26: grid_20qvjmd3.xlsx | F26: 59.598721 | G26: 15.7143 | H26: 35.571762 | I26: 29.316859 | J26: 69.060981 | K26: 37.248452 | M26: 32.059462 | O26: 30.521538 | Q26: 64.849785
... C42: 40513 | D42: 40543 | E42: grid_20qvjmd3.xlsx | F42: 89.504207 | G42: 25.364088 | H42: 74.957791 | I42: 31.513816 | J42: 76.607454 | K42: 45.945372 | M42: 35.46443 | O42: 88.685223 | Q42: 63.605753
C43: 40544 | D43: 40574 | E43: grid_u4lflnxf.xlsx | F43: 93.622475 | G43: 26.411579 | H43: 76.562783 | I43: 28.644927 | J43: 74.872061 | K43: 47.668562 | L43: 65.798097 | M43: 35.841932 | O43: 90.460333 | Q43: 64.752806
C44: 40575 | D44: 40602 | E44: grid_u4lflnxf.xlsx | F44: 95.4253 | G44: 26.756669 | H44: 77.633487 | I44: 28.862271 | J44: 73.393753 | K44: 48.845002 | L44: 65.7804 | M44: 35.889022 | O44: 92.782067 | Q44: 69.388139
C45: 40603 | D45: 40633 | E45: grid_u4lflnxf.xlsx | F45: 93.874926 | G45: 27.756929 | H45: 76.774383 | I45: 29.710509 | J45: 74.125854 | K45: 48.97387 | L45: 65.227999 | M45: 36.411815 | O45: 90.943346 | Q45: 67.364394
C46: 40634 | D46: 40662 | E46: grid_u4lflnxf.xlsx | F46: 93.602783 | G46: 28.988189 | H46: 72.540685 | I46: 30.879799 | J46: 75.436471 | K46: 48.383456 | L46: 66.636359 | M46: 38.868744 | O46: 96.20903 | Q46: 66.007966
C47: 40664 | D47: 40694 | E47: grid_u4lflnxf.xlsx | F47: 88.795109 | G47: 30.946328 | H47: 74.328627 | I47: 35.713826 | J47: 73.023097 | K47: 44.653989 | L47: 65.607458 | M47: 37.667795 | O47: 93.009007 | Q47: 63.979748
C48: 40695 | D48: 40724 | E48: grid_u4lflnxf.xlsx | F48: 95.375727 | G48: 56.029804 | H48: 74.080838 | I48: 36.809689 | J48: 77.535892 | K48: 52.08804 | L48: 62.330578 | M48: 37.246503 | O48: 96.863729 | Q48: 65.548528
C49: 40725 | D49: 40753 | E49: grid_u4lflnxf.xlsx | F49: 100.05162 | G49: 68.681815 | H49: 74.011853 | I49: 36.512546 | J49: 81.598819 | K49: 51.338106 | L49: 64.755779 | M49: 35.750455 | O49: 101.73935 | Q49: 64.266505
C50: 40756 | D50: 40786 | E50: grid_u4lflnxf.xlsx | F50: 95.776255 | G50: 70.200859 | H50: 72.314335 | I50: 42.500767 | J50: 84.590192 | K50: 50.02801 | L50: 52.015324 | M50: 35.546823 | O50: 96.618888 | Q50: 66.020648
C51: 40787 | D51: 40816 | E51: grid_u4lflnxf.xlsx | F51: 94.913168 | G51: 69.135015 | H51: 71.715346 | I51: 44.050682 | J51: 77.791773 | K51: 52.49862 | L51: 47.846899 | M51: 34.144239 | O51: 91.56279 | P51: 76.559818 | Q51: 67.765412
C52: 40817 | D52: 40847 | E52: grid_u4lflnxf.xlsx | F52: 91.558922 | G52: 69.798963 | H52: 70.758934 | I52: 42.506904 | J52: 73.179989 | K52: 52.00476 | L52: 45.508108 | M52: 33.747076 | O52: 88.922057 | P52: 79.121807 | Q52: 66.523768
C53: 40848 | D53: 40877 | E53: grid_u4lflnxf.xlsx | F53: 93.171682 | G53: 72.430879 | H53: 72.102393 | I53: 42.659453 | J53: 76.07585 | K53: 52.202159 | L53: 34.700703 | M53: 36.014483 | O53: 88.764357 | P53: 80.694655 | Q53: 64.768364
C54: 40878 | D54: 40907 | E54: grid_u4lflnxf.xlsx | F54: 89.890505 | G54: 73.104981 | H54: 77.683756 | I54: 45.056467 | J54: 73.975782 | K54: 52.819146 | L54: 34.853093 | M54: 38.877219 | O54: 84.352182 | P54: 80.753413 | Q54: 64.864732
C55: 40909 | D55: 40939 | E55: grid_u4lflnxf.xlsx | F55: 84.736101 | G55: 68.20091 | H55: 68.905556 | I55: 47.299729 | J55: 73.146625 | K55: 53.15513 | L55: 36.775688 | M55: 37.359085 | O55: 82.597094 | P55: 80.910269 | Q55: 65.927215
C56: 40940 | D56: 40968 | E56: grid_u4lflnxf.xlsx | F56: 75.950875 | G56: 67.741762 | H56: 66.122336 | I56: 46.450279 | J56: 68.016136 | K56: 52.866367 | L56: 37.856039 | M56: 37.720662 | O56: 72.058372 | P56: 82.316265 | Q56: 67.117567
C57: 40969 | D57: 40998 | E57: grid_u4lflnxf.xlsx | F57: 75.00194 | G57: 68.723531 | H57: 66.08025 | I57: 49.450181 | J57: 69.387313 | K57: 53.28522 | L57: 38.152722 | M57: 41.117763 | O57: 70.304537 | P57: 84.493428 | Q57: 66.467441
C58: 41000 | D58: 41029 | E58: grid_u4lflnxf.xlsx | F58: 74.819053 | G58: 51.372385 | H58: 63.747209 | I58: 50.208901 | J58: 68.492449 | K58: 51.207799 | L58: 39.329261 | M58: 43.789748 | O58: 71.384355 | P58: 83.0851 | Q58: 70.428615
...

Sheet Revisions 3M
C2: Earnings revisions de três meses
C3: 100 × log(Earnings_t / Earnings_t-3). Valores em percentual logarítmico.
C6: month | D6: date | E6: source_file | F6: IBOV | G6: Communication Services | H6: Consumer Discretionary | I6: Consumer Staples | J6: Energy | K6: Financials | L6: Health Care | M6: Industrials | N6: Information Technology | O6: Materials | P6: Real Estate | Q6: Utilities | R6: Not Classified
C7: 39448 | D7: 39478 | E7: grid_20qvjmd3.xlsx
C8: 39479 | D8: 39507 | E8: grid_20qvjmd3.xlsx
C9: 39508 | D9: 39538 | E9: grid_20qvjmd3.xlsx
C10: 39539 | D10: 39568 | E10: grid_20qvjmd3.xlsx | F10: 7.004419 | G10: -2.6597842 | H10: -3.2260353 | I10: -5.8528082 | J10: 5.0503446 | K10: 3.7996384 | M10: -9.2262992 | O10: 11.103521 | Q10: 12.628445 | R10: -2.8458598
C11: 39569 | D11: 39598 | E11: grid_20qvjmd3.xlsx | F11: 16.177122 | G11: -9.4169869 | H11: -1.7666442 | I11: -4.4984731 | J11: 8.6530376 | K11: 1.3953351 | M11: -10.571606 | O11: 10.977572 | Q11: 8.5122911 | R11: -0.3971906
C12: 39600 | D12: 39629 | E12: grid_20qvjmd3.xlsx | F12: 19.468228 | G12: -6.6774989 | H12: 5.6536205 | I12: 0.74506447 | J12: 6.9670899 | K12: 0.53085475 | M12: -11.215599 | O12: 9.9044318 | Q12: 0.047698664 | R12: -3.4040964
C13: 39630 | D13: 39660 | E13: grid_20qvjmd3.xlsx | F13: 8.3620405 | G13: 3.5942962 | H13: -2.2542113 | I13: -2.1721422 | J13: 10.296783 | K13: -0.586246 | M13: -13.303784 | O13: 6.0552036 | Q13: -1.62912 | R13: -0.36035185
C14: 39661 | D14: 39689 | E14: grid_20qvjmd3.xlsx | F14: 0.063240473 | G14: -3.2789972 | H14: -4.7690444 | I14: 0.15821003 | J14: 7.6552375 | K14: 0.042641409 | M14: 0.25317049 | O14: 5.2615318 | P14: 79.464851 | Q14: 4.0357657 | R14: -0.28526302
C15: 39692 | D15: 39721 | E15: grid_20qvjmd3.xlsx | F15: 13.074671 | G15: -7.4419726 | H15: 15.178614 | I15: 13.099857 | J15: 9.4747465 | K15: -14.38795 | M15: 3.7263324 | O15: 16.500753 | Q15: 16.471185 | R15: 8.0269864
C16: 39722 | D16: 39752 | E16: grid_20qvjmd3.xlsx | F16: 12.157132 | G16: -12.2924 | H16: 23.631533 | I16: 12.087753 | J16: 0.19583469 | K16: -18.746812 | M16: 15.559566 | O16: 17.128965 | Q16: 19.373688 | R16: 4.3221905
C17: 39753 | D17: 39780 | E17: grid_20qvjmd3.xlsx | F17: -2.1201572 | G17: -14.823798 | H17: 21.567833 | I17: 9.7017214 | J17: -4.1100014 | K17: -16.902996 | M17: 0.39282204 | O17: 7.2359767 | Q17: 17.6041 | R17: -1.9594102
C18: 39783 | D18: 39813 | E18: grid_20qvjmd3.xlsx | F18: -25.240373 | G18: 3.372264 | H18: 4.3989215 | I18: -2.4329974 | J18: -22.032956 | K18: -5.1755685 | M18: 1.2806784 | O18: -20.628603 | Q18: 13.488274 | R18: -13.675784
C19: 39814 | D19: 39843 | E19: grid_20qvjmd3.xlsx | F19: -17.284299 | G19: -1.8010223 | H19: -7.1225295 | I19: -2.4768853 | J19: -24.940424 | K19: -18.716214 | M19: -12.982204 | O19: -37.078567 | Q19: 7.5934896 | R19: -28.077523
C20: 39845 | D20: 39871 | E20: grid_20qvjmd3.xlsx | F20: -5.7283972 | G20: 6.0339286 | H20: -13.28794 | I20: -9.8408666 | J20: -21.386269 | K20: -19.579363 | M20: -7.1338182 | O20: -36.622032 | Q20: 4.9566781 | R20: -18.592397
C21: 39873 | D21: 39903 | E21: grid_20qvjmd3.xlsx | F21: -10.70049 | G21: -6.2401325 | H21: -10.840489 | I21: -4.6105341 | J21: -17.161017 | K21: -8.9545327 | M21: -5.7518992 | O21: -45.563516 | Q21: 5.6048786 | R21: -49.946005
C22: 39904 | D22: 39933 | E22: grid_20qvjmd3.xlsx | F22: -19.545819 | G22: -1.6680099 | H22: -3.9223943 | I22: 5.9128658 | J22: -12.671645 | K22: 11.840549 | M22: -2.729654 | O22: -37.230289 | Q22: 4.7703942 | R22: -44.518706
C23: 39934 | D23: 39962 | E23: grid_20qvjmd3.xlsx | F23: -19.630867 | G23: -1.0593136 | H23: 3.3280631 | I23: 16.347614 | J23: -7.4373866 | K23: 11.23496 | M23: -6.2915271 | O23: -45.179154 | Q23: 3.8275198 | R23: -59.04352
C24: 39965 | D24: 39994 | E24: grid_20qvjmd3.xlsx | F24: -11.317423 | G24: 5.3440876 | H24: 3.3489837 | I24: 15.085406 | J24: 2.3494916 | K24: 4.42771 | M24: -18.968542 | O24: -27.987602 | Q24: -4.5257931 | R24: -18.694773
C25: 39995 | D25: 40025 | E25: grid_20qvjmd3.xlsx | F25: -5.7963273 | G25: 5.0676272 | H25: 5.6772306 | I25: 13.610745 | J25: 7.1269009 | K25: 5.5881495 | M25: -17.076088 | O25: -21.775529 | Q25: -3.6163502 | R25: -16.679278
C26: 40026 | D26: 40056 | E26: grid_20qvjmd3.xlsx | F26: -9.1868082 | G26: 4.8558221 | H26: 10.826127 | I26: 12.062642 | J26: 0.93196223 | K26: 9.9743236 | M26: -10.698901 | O26: -12.275548 | Q26: -3.2110536 | R26: -10.117561
