Workbook

Sheet Leia-me
A1: Regimes de earnings e juros do Ibovespa
A2: Tabelas e graficos no formato do Regime Monitor da XP, com a grade earnings x juros
A5: Regra de earnings | B5: Inclinacao OLS do log do BPA esperado 12 meses a frente sobre os ultimos 63 pregoes. O sinal e observado apenas no ultimo pregao de cada mes. Inclinacao positiva e Earnings Up; nao positiva e Earnings Down.
A6: Filtro de mudanca | B6: Uma virada exige dois fechamentos mensais consecutivos do lado oposto e passa a valer no pregao seguinte a segunda confirmacao. Sem media movel, sem winsorizacao, sem banda e sem ajuste pelo Focus.
A7: Regra de juros | B7: Classificacao Hike e Cut da serie do swap Pre-DI de 360 dias. Hike e Juros Up, Cut e Juros Down. Juros Down forcado desde 07/05/2025 ate o fim da amostra, em linha com os reports da XP.
A8: Retornos | B8: O retorno de fechamento a fechamento de t para t+1 e atribuido ao regime vigente em t. Composicao em log, anualizacao por 252 pregoes.
A9: Retorno real | B9: IPCA mensal realizado, com o log da inflacao do mes distribuido igualmente entre os intervalos de pregao daquele mes. Agosto de 2026 fica fora do retorno real por nao haver IPCA realizado.
A10: Frequencia | B10: Dias corridos entre datas efetivas de mudanca de regime.
A11: Amostra | B11: 03/04/2006 a 12/08/2026, 5.036 pregoes classificados, 29 episodios de earnings e 41 episodios combinados.
A13: Abas
A14: Resumo_regimes | B14: Quadro-sintese dos quatro quadrantes, frequencias marginais, estado corrente e os dois graficos de barras.
A15: Graficos | B15: Ibovespa colorido pelo quadrante vigente, swap Pre-DI por regime de juros e a serie de BPA.
A16: Episodios | B16: Os 41 episodios combinados com duracao e desempenho de Ibovespa, CDI, USDBRL e swap.
A17: Ep_por_quadrante | B17: Os mesmos episodios separados por quadrante, no formato das tabelas do report, com mediana e taxa de acerto.
A18: Classes_ativos | B18: Grade de classes de ativos por episodio, com media ponderada e taxa de acerto.
A19: Transicoes | B19: Matriz de transicao entre quadrantes, equivalente ao diagrama do report.
A20: Acumulado_por_regime | B20: Desempenho acumulado do Ibovespa dentro de cada quadrante, com a curva parada nos dias fora do regime.
A21: Trajetoria_eventos | B21: Retorno acumulado do Ibovespa nos ultimos cinco episodios de cada um dos quatro quadrantes, ate 252 pregoes, com um grafico por bloco.
A22: Painel_diario | B22: Base diaria completa. Todas as tabelas apontam para ela.
A23: Mensal | B23: IPCA por mes e a alocacao do log da inflacao entre os intervalos de pregao.
A24: Diagnostico | B24: Sensibilidade, teste de rotacao, bootstrap por episodio, poder preditivo e subamostras.
A26: Fontes
A27: BPA 12 meses a frente | B27: Ibovespa Best EPS.xlsx, planilha Sheet1, de 02/01/2006 a 24/08/2026.
A28: Ibovespa | B28: BCB SGS serie 7 ate 30/12/2013 e serie B3 do projeto desde 02/01/2014. Emenda verificada, retorno de -2,26% em 02/01/2014.
A29: Regimes de juros | B29: swap_pre_di_regimes.csv. Nivel do swap em swap_pre_di_360.csv.
A30: IPCA | B30: BCB SGS 433, arquivos JSON em tmp/earnings_regimes_analysis/ipca, de jan/2006 a jul/2026.
A31: CDI | B31: BCB SGS 12, diario. De 2006 a 2013 baixado do BCB nesta sessao; de 2014 em diante do arquivo cdi_sgs12.csv ja existente no projeto.
A32: USDBRL | B32: PTAX diaria do BCB, arquivos em .codex_eps_analysis/macro.
A34: O que nao foi reproduzido
A35: SMLL, IMA-B 5 e IMA-B 5+ | B35: Nao ha essas series no projeto. As linhas correspondentes da tabela de classes de ativos ficaram de fora.
A36: Setores e cestas de fatores | B36: As abas setoriais MSCI em datasets/ibovespa_msci_return_decomposition sao templates do Bloomberg sem dados carregados. Com um refresh do Bloomberg, as tabelas setoriais e de fatores do report passam a ser reproduziveis.
A37: Limiar de mudanca de regime | B37: O report da XP mostra o nivel de swap que dispararia a virada. Isso depende do modelo proprietario de juros e nao foi replicado.
A39: Como o arquivo esta montado | B39: O Painel_diario e a base de dados. As tabelas-resumo sao formulas com SUMIFS, COUNTIFS e INDEX, entao recalculam sozinhas se a base for estendida. A classificacao de regime em si vem do algoritmo documentado e entra como valor, porque a maquina de estados de confirmacao mensal nao se escreve em formula de planilha.
A40: Serie de BPA | B40: A coluna do BPA 12 meses a frente foi removida desta versao publica por ser dado licenciado da Bloomberg (campo BEst EPS). A inclinacao de 63 pregoes, que e a estatistica usada pela regra, continua na planilha, e todas as tabelas e graficos funcionam sem a serie bruta. Para regenerar o arquivo completo, basta ter o Ibovespa Best EPS.xlsx e rodar src/build_report.py.
A41: Aviso de leitura | B41: Os quatro numeros de retorno sao decomposicao historica, nao previsao. A aba Diagnostico mostra que a ordenacao entre quadrantes e estavel, mas a magnitude do efeito de earnings nao e.
A43: Gerado em 02/09/2026. Nenhum arquivo de entrada foi alterado.

Sheet Resumo_regimes
A1: Ibovespa nos regimes de earnings e juros
A2: Amostra efetiva de 03/04/2006 a 12/08/2026. Todas as celulas abaixo sao formulas sobre Painel_diario e Episodios.
A4: Quadrante | B4: Descricao | C4: % do tempo | D4: Dias corridos | E4: Episodios | F4: Duracao media (dias) | G4: Duracao mediana (dias) | H4: Ibov anual nominal | I4: Ibov anual real | J4: Ibov anual sobre CDI | K4: Dias positivos | L4: Episodios positivos | M4: Taxa de acerto
A5: EU_JD | B5: Earnings Up / Juros Down | C5: =D5/SUM($D$5:$D$8) | D5: =SUMIF(Episodios!$B$5:$B$45,$A5,Episodios!$J$5:$J$45) | E5: =COUNTIF(Episodios!$B$5:$B$45,$A5) | F5: =D5/E5 | G5: =MEDIAN(Ep_por_quadrante!C6:C17) | H5: =EXP(SUMIFS(Painel_diario!$L$2:$L$5037,Painel_diario!$H$2:$H$5037,$A5)*252/COUNTIFS(Painel_diario!$H$2:$H$5037,$A5,Painel_diario!$J$2:$J$5037,1))-1 | I5: =EXP(SUMIFS(Painel_diario!$N$2:$N$5037,Painel_diario!$H$2:$H$5037,$A5)*252/COUNTIFS(Painel_diario!$H$2:$H$5037,$A5,Painel_diario!$K$2:$K$5037,1))-1 | J5: =EXP((SUMIFS(Painel_diario!$L$2:$L$5037,Painel_diario!$H$2:$H$5037,$A5)-SUMIFS(Painel_diario!$P$2:$P$5037,Painel_diario!$H$2:$H$5037,$A5))*252/COUNTIFS(Painel_diario!$H$2:$H$5037,$A5,Painel_diario!$J$2:$J$5037,1))-1 | K5: =COUNTIFS(Painel_diario!$H$2:$H$5037,$A5,Painel_diario!$L$2:$L$5037,">0")/COUNTIFS(Painel_diario!$H$2:$H$5037,$A5,Painel_diario!$J$2:$J$5037,1) | L5: =COUNTIFS(Episodios!$B$5:$B$45,$A5,Episodios!$P$5:$P$45,">0") | M5: =L5/E5
A6: EU_JU | B6: Earnings Up / Juros Up | C6: =D6/SUM($D$5:$D$8) | D6: =SUMIF(Episodios!$B$5:$B$45,$A6,Episodios!$J$5:$J$45) | E6: =COUNTIF(Episodios!$B$5:$B$45,$A6) | F6: =D6/E6 | G6: =MEDIAN(Ep_por_quadrante!C25:C35) | H6: =EXP(SUMIFS(Painel_diario!$L$2:$L$5037,Painel_diario!$H$2:$H$5037,$A6)*252/COUNTIFS(Painel_diario!$H$2:$H$5037,$A6,Painel_diario!$J$2:$J$5037,1))-1 | I6: =EXP(SUMIFS(Painel_diario!$N$2:$N$5037,Painel_diario!$H$2:$H$5037,$A6)*252/COUNTIFS(Painel_diario!$H$2:$H$5037,$A6,Painel_diario!$K$2:$K$5037,1))-1 | J6: =EXP((SUMIFS(Painel_diario!$L$2:$L$5037,Painel_diario!$H$2:$H$5037,$A6)-SUMIFS(Painel_diario!$P$2:$P$5037,Painel_diario!$H$2:$H$5037,$A6))*252/COUNTIFS(Painel_diario!$H$2:$H$5037,$A6,Painel_diario!$J$2:$J$5037,1))-1 | K6: =COUNTIFS(Painel_diario!$H$2:$H$5037,$A6,Painel_diario!$L$2:$L$5037,">0")/COUNTIFS(Painel_diario!$H$2:$H$5037,$A6,Painel_diario!$J$2:$J$5037,1) | L6: =COUNTIFS(Episodios!$B$5:$B$45,$A6,Episodios!$P$5:$P$45,">0") | M6: =L6/E6
A7: ED_JD | B7: Earnings Down / Juros Down | C7: =D7/SUM($D$5:$D$8) | D7: =SUMIF(Episodios!$B$5:$B$45,$A7,Episodios!$J$5:$J$45) | E7: =COUNTIF(Episodios!$B$5:$B$45,$A7) | F7: =D7/E7 | G7: =MEDIAN(Ep_por_quadrante!C43:C51) | H7: =EXP(SUMIFS(Painel_diario!$L$2:$L$5037,Painel_diario!$H$2:$H$5037,$A7)*252/COUNTIFS(Painel_diario!$H$2:$H$5037,$A7,Painel_diario!$J$2:$J$5037,1))-1 | I7: =EXP(SUMIFS(Painel_diario!$N$2:$N$5037,Painel_diario!$H$2:$H$5037,$A7)*252/COUNTIFS(Painel_diario!$H$2:$H$5037,$A7,Painel_diario!$K$2:$K$5037,1))-1 | J7: =EXP((SUMIFS(Painel_diario!$L$2:$L$5037,Painel_diario!$H$2:$H$5037,$A7)-SUMIFS(Painel_diario!$P$2:$P$5037,Painel_diario!$H$2:$H$5037,$A7))*252/COUNTIFS(Painel_diario!$H$2:$H$5037,$A7,Painel_diario!$J$2:$J$5037,1))-1 | K7: =COUNTIFS(Painel_diario!$H$2:$H$5037,$A7,Painel_diario!$L$2:$L$5037,">0")/COUNTIFS(Painel_diario!$H$2:$H$5037,$A7,Painel_diario!$J$2:$J$5037,1) | L7: =COUNTIFS(Episodios!$B$5:$B$45,$A7,Episodios!$P$5:$P$45,">0") | M7: =L7/E7
A8: ED_JU | B8: Earnings Down / Juros Up | C8: =D8/SUM($D$5:$D$8) | D8: =SUMIF(Episodios!$B$5:$B$45,$A8,Episodios!$J$5:$J$45) | E8: =COUNTIF(Episodios!$B$5:$B$45,$A8) | F8: =D8/E8 | G8: =MEDIAN(Ep_por_quadrante!C59:C67) | H8: =EXP(SUMIFS(Painel_diario!$L$2:$L$5037,Painel_diario!$H$2:$H$5037,$A8)*252/COUNTIFS(Painel_diario!$H$2:$H$5037,$A8,Painel_diario!$J$2:$J$5037,1))-1 | I8: =EXP(SUMIFS(Painel_diario!$N$2:$N$5037,Painel_diario!$H$2:$H$5037,$A8)*252/COUNTIFS(Painel_diario!$H$2:$H$5037,$A8,Painel_diario!$K$2:$K$5037,1))-1 | J8: =EXP((SUMIFS(Painel_diario!$L$2:$L$5037,Painel_diario!$H$2:$H$5037,$A8)-SUMIFS(Painel_diario!$P$2:$P$5037,Painel_diario!$H$2:$H$5037,$A8))*252/COUNTIFS(Painel_diario!$H$2:$H$5037,$A8,Painel_diario!$J$2:$J$5037,1))-1 | K8: =COUNTIFS(Painel_diario!$H$2:$H$5037,$A8,Painel_diario!$L$2:$L$5037,">0")/COUNTIFS(Painel_diario!$H$2:$H$5037,$A8,Painel_diario!$J$2:$J$5037,1) | L8: =COUNTIFS(Episodios!$B$5:$B$45,$A8,Episodios!$P$5:$P$45,">0") | M8: =L8/E8
B9: Total / Ibovespa na amostra | C9: =SUM(C5:C8) | D9: =SUM(D5:D8) | E9: =SUM(E5:E8) | H9: =EXP(SUM(Painel_diario!$L$2:$L$5037)*252/COUNTIF(Painel_diario!$J$2:$J$5037,1))-1 | I9: =EXP(SUM(Painel_diario!$N$2:$N$5037)*252/COUNTIF(Painel_diario!$K$2:$K$5037,1))-1 | J9: =EXP((SUM(Painel_diario!$L$2:$L$5037)-SUM(Painel_diario!$P$2:$P$5037))*252/COUNTIF(Painel_diario!$J$2:$J$5037,1))-1 | K9: =COUNTIF(Painel_diario!$L$2:$L$5037,">0")/COUNTIF(Painel_diario!$J$2:$J$5037,1)
A11: Frequencias marginais
A12: Classificacao | B12: Dias corridos | C12: % do tempo | D12: Ibov anual real
A13: Earnings Up | B13: =SUMIF(Episodios!$B$5:$B$45,"EU_JD",Episodios!$J$5:$J$45)+SUMIF(Episodios!$B$5:$B$45,"EU_JU",Episodios!$J$5:$J$45) | C13: =B13/SUM($D$5:$D$8) | D13: =EXP(SUMIFS(Painel_diario!$N$2:$N$5037,Painel_diario!$F$2:$F$5037,"Up")*252/COUNTIFS(Painel_diario!$F$2:$F$5037,"Up",Painel_diario!$K$2:$K$5037,1))-1
A14: Earnings Down | B14: =SUMIF(Episodios!$B$5:$B$45,"ED_JD",Episodios!$J$5:$J$45)+SUMIF(Episodios!$B$5:$B$45,"ED_JU",Episodios!$J$5:$J$45) | C14: =B14/SUM($D$5:$D$8) | D14: =EXP(SUMIFS(Painel_diario!$N$2:$N$5037,Painel_diario!$F$2:$F$5037,"Down")*252/COUNTIFS(Painel_diario!$F$2:$F$5037,"Down",Painel_diario!$K$2:$K$5037,1))-1
A15: Juros Up | B15: =SUMIF(Episodios!$B$5:$B$45,"EU_JU",Episodios!$J$5:$J$45)+SUMIF(Episodios!$B$5:$B$45,"ED_JU",Episodios!$J$5:$J$45) | C15: =B15/SUM($D$5:$D$8) | D15: =EXP(SUMIFS(Painel_diario!$N$2:$N$5037,Painel_diario!$G$2:$G$5037,"Up")*252/COUNTIFS(Painel_diario!$G$2:$G$5037,"Up",Painel_diario!$K$2:$K$5037,1))-1
A16: Juros Down | B16: =SUMIF(Episodios!$B$5:$B$45,"EU_JD",Episodios!$J$5:$J$45)+SUMIF(Episodios!$B$5:$B$45,"ED_JD",Episodios!$J$5:$J$45) | C16: =B16/SUM($D$5:$D$8) | D16: =EXP(SUMIFS(Painel_diario!$N$2:$N$5037,Painel_diario!$G$2:$G$5037,"Down")*252/COUNTIFS(Painel_diario!$G$2:$G$5037,"Down",Painel_diario!$K$2:$K$5037,1))-1
A18: Estado corrente em 12/08/2026
A19: Regime de earnings | B19: Earnings Up desde 01/12/2025
A20: Regime de juros | B20: Juros Down desde 07/05/2025
A21: Quadrante combinado | B21: Earnings Up / Juros Down desde 01/12/2025
A22: Ultima observacao comum | B22: 12/08/2026
A23: Ultimo IPCA realizado | B23: julho de 2026
A26: Duracao mediana preenchida na aba Ep_por_quadrante, onde os episodios de cada quadrante ficam em linhas contiguas.

Sheet Graficos
A1: Graficos do report
A2: As series vem do Painel_diario. O Ibovespa aparece em quatro colunas, uma por quadrante, para colorir o nivel do indice conforme o regime vigente.

Sheet Episodios
A1: Episodios combinados de earnings e juros
A2: Um episodio comeca no primeiro pregao em que o quadrante vigora e termina no primeiro pregao do quadrante seguinte. Metricas calculadas por formula sobre o Painel_diario.
A4: # | B4: Quadrante | C4: Descricao | D4: Earnings | E4: Juros | F4: Inicio | G4: Fim | H4: Fim exclusivo | I4: Ultimo pregao | J4: Dias corridos | K4: Pregoes | L4: Intervalos | M4: Interv. c/ IPCA | N4: Ibov total nominal | O4: Ibov anual nominal | P4: Ibov total real | Q4: Ibov anual real | R4: CDI anual | S4: Ibov anual sobre CDI | T4: USDBRL anual | U4: Swap 360d (bps) | V4: Corrente
A5: 1 | B5: EU_JD | C5: Earnings Up / Juros Down | D5: Up | E5: Down | F5: 38810 | G5: 38869 | H5: 38869 | I5: 38868 | J5: =G5-F5 | K5: =COUNTIFS(Painel_diario!$A$2:$A$5037,">="&$F5,Painel_diario!$A$2:$A$5037,"<"&$H5) | L5: =COUNTIFS(Painel_diario!$A$2:$A$5037,">="&$F5,Painel_diario!$A$2:$A$5037,"<"&$H5,Painel_diario!$J$2:$J$5037,1) | M5: =COUNTIFS(Painel_diario!$A$2:$A$5037,">="&$F5,Painel_diario!$A$2:$A$5037,"<"&$H5,Painel_diario!$K$2:$K$5037,1) | N5: =EXP(SUMIFS(Painel_diario!$L$2:$L$5037,Painel_diario!$A$2:$A$5037,">="&$F5,Painel_diario!$A$2:$A$5037,"<"&$H5))-1 | O5: =IF(L5=0,"",EXP(SUMIFS(Painel_diario!$L$2:$L$5037,Painel_diario!$A$2:$A$5037,">="&$F5,Painel_diario!$A$2:$A$5037,"<"&$H5)*252/L5)-1) | P5: =EXP(SUMIFS(Painel_diario!$N$2:$N$5037,Painel_diario!$A$2:$A$5037,">="&$F5,Painel_diario!$A$2:$A$5037,"<"&$H5))-1 | Q5: =IF(M5=0,"",EXP(SUMIFS(Painel_diario!$N$2:$N$5037,Painel_diario!$A$2:$A$5037,">="&$F5,Painel_diario!$A$2:$A$5037,"<"&$H5)*252/M5)-1) | R5: =IF(L5=0,"",EXP(SUMIFS(Painel_diario!$P$2:$P$5037,Painel_diario!$A$2:$A$5037,">="&$F5,Painel_diario!$A$2:$A$5037,"<"&$H5)*252/L5)-1) | S5: =IF(L5=0,"",EXP((SUMIFS(Painel_diario!$L$2:$L$5037,Painel_diario!$A$2:$A$5037,">="&$F5,Painel_diario!$A$2:$A$5037,"<"&$H5)-SUMIFS(Painel_diario!$P$2:$P$5037,Painel_diario!$A$2:$A$5037,">="&$F5,Painel_diario!$A$2:$A$5037,"<"&$H5))*252/L5)-1) | T5: =IF(L5=0,"",EXP(SUMIFS(Painel_diario!$Q$2:$Q$5037,Painel_diario!$A$2:$A$5037,">="&$F5,Painel_diario!$A$2:$A$5037,"<"&$H5)*252/L5)-1) | U5: =(INDEX(Painel_diario!$S$2:$S$5037,MATCH($I5,Painel_diario!$A$2:$A$5037,0))-INDEX(Painel_diario!$S$2:$S$5037,MATCH($F5,Painel_diario!$A$2:$A$5037,0)))*100
A6: 2 | B6: ED_JD | C6: Earnings Down / Juros Down | D6: Down | E6: Down | F6: 38869 | G6: 39022 | H6: 39022 | I6: 39021 | J6: =G6-F6 | K6: =COUNTIFS(Painel_diario!$A$2:$A$5037,">="&$F6,Painel_diario!$A$2:$A$5037,"<"&$H6) | L6: =COUNTIFS(Painel_diario!$A$2:$A$5037,">="&$F6,Painel_diario!$A$2:$A$5037,"<"&$H6,Painel_diario!$J$2:$J$5037,1) | M6: =COUNTIFS(Painel_diario!$A$2:$A$5037,">="&$F6,Painel_diario!$A$2:$A$5037,"<"&$H6,Painel_diario!$K$2:$K$5037,1) | N6: =EXP(SUMIFS(Painel_diario!$L$2:$L$5037,Painel_diario!$A$2:$A$5037,">="&$F6,Painel_diario!$A$2:$A$5037,"<"&$H6))-1 | O6: =IF(L6=0,"",EXP(SUMIFS(Painel_diario!$L$2:$L$5037,Painel_diario!$A$2:$A$5037,">="&$F6,Painel_diario!$A$2:$A$5037,"<"&$H6)*252/L6)-1) | P6: =EXP(SUMIFS(Painel_diario!$N$2:$N$5037,Painel_diario!$A$2:$A$5037,">="&$F6,Painel_diario!$A$2:$A$5037,"<"&$H6))-1 | Q6: =IF(M6=0,"",EXP(SUMIFS(Painel_diario!$N$2:$N$5037,Painel_diario!$A$2:$A$5037,">="&$F6,Painel_diario!$A$2:$A$5037,"<"&$H6)*252/M6)-1) | R6: =IF(L6=0,"",EXP(SUMIFS(Painel_diario!$P$2:$P$5037,Painel_diario!$A$2:$A$5037,">="&$F6,Painel_diario!$A$2:$A$5037,"<"&$H6)*252/L6)-1) | S6: =IF(L6=0,"",EXP((SUMIFS(Painel_diario!$L$2:$L$5037,Painel_diario!$A$2:$A$5037,">="&$F6,Painel_diario!$A$2:$A$5037,"<"&$H6)-SUMIFS(Painel_diario!$P$2:$P$5037,Painel_diario!$A$2:$A$5037,">="&$F6,Painel_diario!$A$2:$A$5037,"<"&$H6))*252/L6)-1) | T6: =IF(L6=0,"",EXP(SUMIFS(Painel_diario!$Q$2:$Q$5037,Painel_diario!$A$2:$A$5037,">="&$F6,Painel_diario!$A$2:$A$5037,"<"&$H6)*252/L6)-1) | U6: =(INDEX(Painel_diario!$S$2:$S$5037,MATCH($I6,Painel_diario!$A$2:$A$5037,0))-INDEX(Painel_diario!$S$2:$S$5037,MATCH($F6,Painel_diario!$A$2:$A$5037,0)))*100
A7: 3 | B7: EU_JD | C7: Earnings Up / Juros Down | D7: Up | E7: Down | F7: 39022 | G7: 39331 | H7: 39331 | I7: 39330 | J7: =G7-F7 | K7: =COUNTIFS(Painel_diario!$A$2:$A$5037,">="&$F7,Painel_diario!$A$2:$A$5037,"<"&$H7) | L7: =COUNTIFS(Painel_diario!$A$2:$A$5037,">="&$F7,Painel_diario!$A$2:$A$5037,"<"&$H7,Painel_diario!$J$2:$J$5037,1) | M7: =COUNTIFS(Painel_diario!$A$2:$A$5037,">="&$F7,Painel_diario!$A$2:$A$5037,"<"&$H7,Painel_diario!$K$2:$K$5037,1) | N7: =EXP(SUMIFS(Painel_diario!$L$2:$L$5037,Painel_diario!$A$2:$A$5037,">="&$F7,Painel_diario!$A$2:$A$5037,"<"&$H7))-1 | O7: =IF(L7=0,"",EXP(SUMIFS(Painel_diario!$L$2:$L$5037,Painel_diario!$A$2:$A$5037,">="&$F7,Painel_diario!$A$2:$A$5037,"<"&$H7)*252/L7)-1) | P7: =EXP(SUMIFS(Painel_diario!$N$2:$N$5037,Painel_diario!$A$2:$A$5037,">="&$F7,Painel_diario!$A$2:$A$5037,"<"&$H7))-1 | Q7: =IF(M7=0,"",EXP(SUMIFS(Painel_diario!$N$2:$N$5037,Painel_diario!$A$2:$A$5037,">="&$F7,Painel_diario!$A$2:$A$5037,"<"&$H7)*252/M7)-1) | R7: =IF(L7=0,"",EXP(SUMIFS(Painel_diario!$P$2:$P$5037,Painel_diario!$A$2:$A$5037,">="&$F7,Painel_diario!$A$2:$A$5037,"<"&$H7)*252/L7)-1) | S7: =IF(L7=0,"",EXP((SUMIFS(Painel_diario!$L$2:$L$5037,Painel_diario!$A$2:$A$5037,">="&$F7,Painel_diario!$A$2:$A$5037,"<"&$H7)-SUMIFS(Painel_diario!$P$2:$P$5037,Painel_diario!$A$2:$A$5037,">="&$F7,Painel_diario!$A$2:$A$5037,"<"&$H7))*252/L7)-1) | T7: =IF(L7=0,"",EXP(SUMIFS(Painel_diario!$Q$2:$Q$5037,Painel_diario!$A$2:$A$5037,">="&$F7,Painel_diario!$A$2:$A$5037,"<"&$H7)*252/L7)-1) | U7: =(INDEX(Painel_diario!$S$2:$S$5037,MATCH($I7,Painel_diario!$A$2:$A$5037,0))-INDEX(Painel_diario!$S$2:$S$5037,MATCH($F7,Painel_diario!$A$2:$A$5037,0)))*100
A8: 4 | B8: EU_JU | C8: Earnings Up / Juros Up | D8: Up | E8: Up | F8: 39331 | G8: 39449 | H8: 39449 | I8: 39444 | J8: =G8-F8 | K8: =COUNTIFS(Painel_diario!$A$2:$A$5037,">="&$F8,Painel_diario!$A$2:$A$5037,"<"&$H8) | L8: =COUNTIFS(Painel_diario!$A$2:$A$5037,">="&$F8,Painel_diario!$A$2:$A$5037,"<"&$H8,Painel_diario!$J$2:$J$5037,1) | M8: =COUNTIFS(Painel_diario!$A$2:$A$5037,">="&$F8,Painel_diario!$A$2:$A$5037,"<"&$H8,Painel_diario!$K$2:$K$5037,1) | N8: =EXP(SUMIFS(Painel_diario!$L$2:$L$5037,Painel_diario!$A$2:$A$5037,">="&$F8,Painel_diario!$A$2:$A$5037,"<"&$H8))-1 | O8: =IF(L8=0,"",EXP(SUMIFS(Painel_diario!$L$2:$L$5037,Painel_diario!$A$2:$A$5037,">="&$F8,Painel_diario!$A$2:$A$5037,"<"&$H8)*252/L8)-1) | P8: =EXP(SUMIFS(Painel_diario!$N$2:$N$5037,Painel_diario!$A$2:$A$5037,">="&$F8,Painel_diario!$A$2:$A$5037,"<"&$H8))-1 | Q8: =IF(M8=0,"",EXP(SUMIFS(Painel_diario!$N$2:$N$5037,Painel_diario!$A$2:$A$5037,">="&$F8,Painel_diario!$A$2:$A$5037,"<"&$H8)*252/M8)-1) | R8: =IF(L8=0,"",EXP(SUMIFS(Painel_diario!$P$2:$P$5037,Painel_diario!$A$2:$A$5037,">="&$F8,Painel_diario!$A$2:$A$5037,"<"&$H8)*252/L8)-1) | S8: =IF(L8=0,"",EXP((SUMIFS(Painel_diario!$L$2:$L$5037,Painel_diario!$A$2:$A$5037,">="&$F8,Painel_diario!$A$2:$A$5037,"<"&$H8)-SUMIFS(Painel_diario!$P$2:$P$5037,Painel_diario!$A$2:$A$5037,">="&$F8,Painel_diario!$A$2:$A$5037,"<"&$H8))*252/L8)-1) | T8: =IF(L8=0,"",EXP(SUMIFS(Painel_diario!$Q$2:$Q$5037,Painel_diario!$A$2:$A$5037,">="&$F8,Painel_diario!$A$2:$A$5037,"<"&$H8)*252/L8)-1) | U8: =(INDEX(Painel_diario!$S$2:$S$5037,MATCH($I8,Painel_diario!$A$2:$A$5037,0))-INDEX(Painel_diario!$S$2:$S$5037,MATCH($F8,Painel_diario!$A$2:$A$5037,0)))*100
A9: 5 | B9: ED_JU | C9: Earnings Down / Juros Up | D9: Down | E9: Up | F9: 39449 | G9: 39510 | H9: 39510 | I9: 39506 | J9: =G9-F9 | K9: =COUNTIFS(Painel_diario!$A$2:$A$5037,">="&$F9,Painel_diario!$A$2:$A$5037,"<"&$H9) | L9: =COUNTIFS(Painel_diario!$A$2:$A$5037,">="&$F9,Painel_diario!$A$2:$A$5037,"<"&$H9,Painel_diario!$J$2:$J$5037,1) | M9: =COUNTIFS(Painel_diario!$A$2:$A$5037,">="&$F9,Painel_diario!$A$2:$A$5037,"<"&$H9,Painel_diario!$K$2:$K$5037,1) | N9: =EXP(SUMIFS(Painel_diario!$L$2:$L$5037,Painel_diario!$A$2:$A$5037,">="&$F9,Painel_diario!$A$2:$A$5037,"<"&$H9))-1 | O9: =IF(L9=0,"",EXP(SUMIFS(Painel_diario!$L$2:$L$5037,Painel_diario!$A$2:$A$5037,">="&$F9,Painel_diario!$A$2:$A$5037,"<"&$H9)*252/L9)-1) | P9: =EXP(SUMIFS(Painel_diario!$N$2:$N$5037,Painel_diario!$A$2:$A$5037,">="&$F9,Painel_diario!$A$2:$A$5037,"<"&$H9))-1 | Q9: =IF(M9=0,"",EXP(SUMIFS(Painel_diario!$N$2:$N$5037,Painel_diario!$A$2:$A$5037,">="&$F9,Painel_diario!$A$2:$A$5037,"<"&$H9)*252/M9)-1) | R9: =IF(L9=0,"",EXP(SUMIFS(Painel_diario!$P$2:$P$5037,Painel_diario!$A$2:$A$5037,">="&$F9,Painel_diario!$A$2:$A$5037,"<"&$H9)*252/L9)-1) | S9: =IF(L9=0,"",EXP((SUMIFS(Painel_diario!$L$2:$L$5037,Painel_diario!$A$2:$A$5037,">="&$F9,Painel_diario!$A$2:$A$5037,"<"&$H9)-SUMIFS(Painel_diario!$P$2:$P$5037,Painel_diario!$A$2:$A$5037,">="&$F9,Painel_diario!$A$2:$A$5037,"<"&$H9))*252/L9)-1) | T9: =IF(L9=0,"",EXP(SUMIFS(Painel_diario!$Q$2:$Q$5037,Painel_diario!$A$2:$A$5037,">="&$F9,Painel_diario!$A$2:$A$5037,"<"&$H9)*252/L9)-1) | U9: =(INDEX(Painel_diario!$S$2:$S$5037,MATCH($I9,Painel_diario!$A$2:$A$5037,0))-INDEX(Painel_diario!$S$2:$S$5037,MATCH($F9,Painel_diario!$A$2:$A$5037,0)))*100
A10: 6 | B10: EU_JU | C10: Earnings Up / Juros Up | D10: Up | E10: Up | F10: 39510 | G10: 39792 | H10: 39792 | I10: 39791 | J10: =G10-F10 | K10: =COUNTIFS(Painel_diario!$A$2:$A$5037,">="&$F10,Painel_diario!$A$2:$A$5037,"<"&$H10) | L10: =COUNTIFS(Painel_diario!$A$2:$A$5037,">="&$F10,Painel_diario!$A$2:$A$5037,"<"&$H10,Painel_diario!$J$2:$J$5037,1) | M10: =COUNTIFS(Painel_diario!$A$2:$A$5037,">="&$F10,Painel_diario!$A$2:$A$5037,"<"&$H10,Painel_diario!$K$2:$K$5037,1) | N10: =EXP(SUMIFS(Painel_diario!$L$2:$L$5037,Painel_diario!$A$2:$A$5037,">="&$F10,Painel_diario!$A$2:$A$5037,"<"&$H10))-1 | O10: =IF(L10=0,"",EXP(SUMIFS(Painel_diario!$L$2:$L$5037,Painel_diario!$A$2:$A$5037,">="&$F10,Painel_diario!$A$2:$A$5037,"<"&$H10)*252/L10)-1) | P10: =EXP(SUMIFS(Painel_diario!$N$2:$N$5037,Painel_diario!$A$2:$A$5037,">="&$F10,Painel_diario!$A$2:$A$5037,"<"&$H10))-1 | Q10: =IF(M10=0,"",EXP(SUMIFS(Painel_diario!$N$2:$N$5037,Painel_diario!$A$2:$A$5037,">="&$F10,Painel_diario!$A$2:$A$5037,"<"&$H10)*252/M10)-1) | R10: =IF(L10=0,"",EXP(SUMIFS(Painel_diario!$P$2:$P$5037,Painel_diario!$A$2:$A$5037,">="&$F10,Painel_diario!$A$2:$A$5037,"<"&$H10)*252/L10)-1) | S10: =IF(L10=0,"",EXP((SUMIFS(Painel_diario!$L$2:$L$5037,Painel_diario!$A$2:$A$5037,">="&$F10,Painel_diario!$A$2:$A$5037,"<"&$H10)-SUMIFS(Painel_diario!$P$2:$P$5037,Painel_diario!$A$2:$A$5037,">="&$F10,Painel_diario!$A$2:$A$5037,"<"&$H10))*252/L10)-1) | T10: =IF(L10=0,"",EXP(SUMIFS(Painel_diario!$Q$2:$Q$5037,Painel_diario!$A$2:$A$5037,">="&$F10,Painel_diario!$A$2:$A$5037,"<"&$H10)*252/L10)-1) | U10: =(INDEX(Painel_diario!$S$2:$S$5037,MATCH($I10,Painel_diario!$A$2:$A$5037,0))-INDEX(Painel_diario!$S$2:$S$5037,MATCH($F10,Painel_diario!$A$2:$A$5037,0)))*100
A11: 7 | B11: EU_JD | C11: Earnings Up / Juros Down | D11: Up | E11: Down | F11: 39792 | G11: 39815 | H11: 39815 | I11: 39812 | J11: =G11-F11 | K11: =COUNTIFS(Painel_diario!$A$2:$A$5037,">="&$F11,Painel_diario!$A$2:$A$5037,"<"&$H11) | L11: =COUNTIFS(Painel_diario!$A$2:$A$5037,">="&$F11,Painel_diario!$A$2:$A$5037,"<"&$H11,Painel_diario!$J$2:$J$5037,1) | M11: =COUNTIFS(Painel_diario!$A$2:$A$5037,">="&$F11,Painel_diario!$A$2:$A$5037,"<"&$H11,Painel_diario!$K$2:$K$5037,1) | N11: =EXP(SUMIFS(Painel_diario!$L$2:$L$5037,Painel_diario!$A$2:$A$5037,">="&$F11,Painel_diario!$A$2:$A$5037,"<"&$H11))-1 | O11: =IF(L11=0,"",EXP(SUMIFS(Painel_diario!$L$2:$L$5037,Painel_diario!$A$2:$A$5037,">="&$F11,Painel_diario!$A$2:$A$5037,"<"&$H11)*252/L11)-1) | P11: =EXP(SUMIFS(Painel_diario!$N$2:$N$5037,Painel_diario!$A$2:$A$5037,">="&$F11,Painel_diario!$A$2:$A$5037,"<"&$H11))-1 | Q11: =IF(M11=0,"",EXP(SUMIFS(Painel_diario!$N$2:$N$5037,Painel_diario!$A$2:$A$5037,">="&$F11,Painel_diario!$A$2:$A$5037,"<"&$H11)*252/M11)-1) | R11: =IF(L11=0,"",EXP(SUMIFS(Painel_diario!$P$2:$P$5037,Painel_diario!$A$2:$A$5037,">="&$F11,Painel_diario!$A$2:$A$5037,"<"&$H11)*252/L11)-1) | S11: =IF(L11=0,"",EXP((SUMIFS(Painel_diario!$L$2:$L$5037,Painel_diario!$A$2:$A$5037,">="&$F11,Painel_diario!$A$2:$A$5037,"<"&$H11)-SUMIFS(Painel_diario!$P$2:$P$5037,Painel_diario!$A$2:$A$5037,">="&$F11,Painel_diario!$A$2:$A$5037,"<"&$H11))*252/L11)-1) | T11: =IF(L11=0,"",EXP(SUMIFS(Painel_diario!$Q$2:$Q$5037,Painel_diario!$A$2:$A$5037,">="&$F11,Painel_diario!$A$2:$A$5037,"<"&$H11)*252/L11)-1) | U11: =(INDEX(Painel_diario!$S$2:$S$5037,MATCH($I11,Painel_diario!$A$2:$A$5037,0))-INDEX(Painel_diario!$S$2:$S$5037,MATCH($F11,Painel_diario!$A$2:$A$5037,0)))*100
A12: 8 | B12: ED_JD | C12: Earnings Down / Juros Down | D12: Down | E12: Down | F12: 39815 | G12: 40057 | H12: 40057 | I12: 40056 | J12: =G12-F12 | K12: =COUNTIFS(Painel_diario!$A$2:$A$5037,">="&$F12,Painel_diario!$A$2:$A$5037,"<"&$H12) | L12: =COUNTIFS(Painel_diario!$A$2:$A$5037,">="&$F12,Painel_diario!$A$2:$A$5037,"<"&$H12,Painel_diario!$J$2:$J$5037,1) | M12: =COUNTIFS(Painel_diario!$A$2:$A$5037,">="&$F12,Painel_diario!$A$2:$A$5037,"<"&$H12,Painel_diario!$K$2:$K$5037,1) | N12: =EXP(SUMIFS(Painel_diario!$L$2:$L$5037,Painel_diario!$A$2:$A$5037,">="&$F12,Painel_diario!$A$2:$A$5037,"<"&$H12))-1 | O12: =IF(L12=0,"",EXP(SUMIFS(Painel_diario!$L$2:$L$5037,Painel_diario!$A$2:$A$5037,">="&$F12,Painel_diario!$A$2:$A$5037,"<"&$H12)*252/L12)-1) | P12: =EXP(SUMIFS(Painel_diario!$N$2:$N$5037,Painel_diario!$A$2:$A$5037,">="&$F12,Painel_diario!$A$2:$A$5037,"<"&$H12))-1 | Q12: =IF(M12=0,"",EXP(SUMIFS(Painel_diario!$N$2:$N$5037,Painel_diario!$A$2:$A$5037,">="&$F12,Painel_diario!$A$2:$A$5037,"<"&$H12)*252/M12)-1) | R12: =IF(L12=0,"",EXP(SUMIFS(Painel_diario!$P$2:$P$5037,Painel_diario!$A$2:$A$5037,">="&$F12,Painel_diario!$A$2:$A$5037,"<"&$H12)*252/L12)-1) | S12: =IF(L12=0,"",EXP((SUMIFS(Painel_diario!$L$2:$L$5037,Painel_diario!$A$2:$A$5037,">="&$F12,Painel_diario!$A$2:$A$5037,"<"&$H12)-SUMIFS(Painel_diario!$P$2:$P$5037,Painel_diario!$A$2:$A$5037,">="&$F12,Painel_diario!$A$2:$A$5037,"<"&$H12))*252/L12)-1) | T12: =IF(L12=0,"",EXP(SUMIFS(Painel_diario!$Q$2:$Q$5037,Painel_diario!$A$2:$A$5037,">="&$F12,Painel_diario!$A$2:$A$5037,"<"&$H12)*252/L12)-1) | U12: =(INDEX(Painel_diario!$S$2:$S$5037,MATCH($I12,Painel_diario!$A$2:$A$5037,0))-INDEX(Painel_diario!$S$2:$S$5037,MATCH($F12,Painel_diario!$A$2:$A$5037,0)))*100
A13: 9 | B13: EU_JD | C13: Earnings Up / Juros Down | D13: Up | E13: Down | F13: 40057 | G13: 40091 | H13: 40091 | I13: 40088 | J13: =G13-F13 | K13: =COUNTIFS(Painel_diario!$A$2:$A$5037,">="&$F13,Painel_diario!$A$2:$A$5037,"<"&$H13) | L13: =COUNTIFS(Painel_diario!$A$2:$A$5037,">="&$F13,Painel_diario!$A$2:$A$5037,"<"&$H13,Painel_diario!$J$2:$J$5037,1) | M13: =COUNTIFS(Painel_diario!$A$2:$A$5037,">="&$F13,Painel_diario!$A$2:$A$5037,"<"&$H13,Painel_diario!$K$2:$K$5037,1) | N13: =EXP(SUMIFS(Painel_diario!$L$2:$L$5037,Painel_diario!$A$2:$A$5037,">="&$F13,Painel_diario!$A$2:$A$5037,"<"&$H13))-1 | O13: =IF(L13=0,"",EXP(SUMIFS(Painel_diario!$L$2:$L$5037,Painel_diario!$A$2:$A$5037,">="&$F13,Painel_diario!$A$2:$A$5037,"<"&$H13)*252/L13)-1) | P13: =EXP(SUMIFS(Painel_diario!$N$2:$N$5037,Painel_diario!$A$2:$A$5037,">="&$F13,Painel_diario!$A$2:$A$5037,"<"&$H13))-1 | Q13: =IF(M13=0,"",EXP(SUMIFS(Painel_diario!$N$2:$N$5037,Painel_diario!$A$2:$A$5037,">="&$F13,Painel_diario!$A$2:$A$5037,"<"&$H13)*252/M13)-1) | R13: =IF(L13=0,"",EXP(SUMIFS(Painel_diario!$P$2:$P$5037,Painel_diario!$A$2:$A$5037,">="&$F13,Painel_diario!$A$2:$A$5037,"<"&$H13)*252/L13)-1) | S13: =IF(L13=0,"",EXP((SUMIFS(Painel_diario!$L$2:$L$5037,Painel_diario!$A$2:$A$5037,">="&$F13,Painel_diario!$A$2:$A$5037,"<"&$H13)-SUMIFS(Painel_diario!$P$2:$P$5037,Painel_diario!$A$2:$A$5037,">="&$F13,Painel_diario!$A$2:$A$5037,"<"&$H13))*252/L13)-1) | T13: =IF(L13=0,"",EXP(SUMIFS(Painel_diario!$Q$2:$Q$5037,Painel_diario!$A$2:$A$5037,">="&$F13,Painel_diario!$A$2:$A$5037,"<"&$H13)*252/L13)-1) | U13: =(INDEX(Painel_diario!$S$2:$S$5037,MATCH($I13,Painel_diario!$A$2:$A$5037,0))-INDEX(Painel_diario!$S$2:$S$5037,MATCH($F13,Painel_diario!$A$2:$A$5037,0)))*100
A14: 10 | B14: EU_JU | C14: Earnings Up / Juros Up | D14: Up | E14: Up | F14: 40091 | G14: 40513 | H14: 40513 | I14: 40512 | J14: =G14-F14 | K14: =COUNTIFS(Painel_diario!$A$2:$A$5037,">="&$F14,Painel_diario!$A$2:$A$5037,"<"&$H14) | L14: =COUNTIFS(Painel_diario!$A$2:$A$5037,">="&$F14,Painel_diario!$A$2:$A$5037,"<"&$H14,Painel_diario!$J$2:$J$5037,1) | M14: =COUNTIFS(Painel_diario!$A$2:$A$5037,">="&$F14,Painel_diario!$A$2:$A$5037,"<"&$H14,Painel_diario!$K$2:$K$5037,1) | N14: =EXP(SUMIFS(Painel_diario!$L$2:$L$5037,Painel_diario!$A$2:$A$5037,">="&$F14,Painel_diario!$A$2:$A$5037,"<"&$H14))-1 | O14: =IF(L14=0,"",EXP(SUMIFS(Painel_diario!$L$2:$L$5037,Painel_diario!$A$2:$A$5037,">="&$F14,Painel_diario!$A$2:$A$5037,"<"&$H14)*252/L14)-1) | P14: =EXP(SUMIFS(Painel_diario!$N$2:$N$5037,Painel_diario!$A$2:$A$5037,">="&$F14,Painel_diario!$A$2:$A$5037,"<"&$H14))-1 | Q14: =IF(M14=0,"",EXP(SUMIFS(Painel_diario!$N$2:$N$5037,Painel_diario!$A$2:$A$5037,">="&$F14,Painel_diario!$A$2:$A$5037,"<"&$H14)*252/M14)-1) | R14: =IF(L14=0,"",EXP(SUMIFS(Painel_diario!$P$2:$P$5037,Painel_diario!$A$2:$A$5037,">="&$F14,Painel_diario!$A$2:$A$5037,"<"&$H14)*252/L14)-1) | S14: =IF(L14=0,"",EXP((SUMIFS(Painel_diario!$L$2:$L$5037,Painel_diario!$A$2:$A$5037,">="&$F14,Painel_diario!$A$2:$A$5037,"<"&$H14)-SUMIFS(Painel_diario!$P$2:$P$5037,Painel_diario!$A$2:$A$5037,">="&$F14,Painel_diario!$A$2:$A$5037,"<"&$H14))*252/L14)-1) | T14: =IF(L14=0,"",EXP(SUMIFS(Painel_diario!$Q$2:$Q$5037,Painel_diario!$A$2:$A$5037,">="&$F14,Painel_diario!$A$2:$A$5037,"<"&$H14)*252/L14)-1) | U14: =(INDEX(Painel_diario!$S$2:$S$5037,MATCH($I14,Painel_diario!$A$2:$A$5037,0))-INDEX(Painel_diario!$S$2:$S$5037,MATCH($F14,Painel_diario!$A$2:$A$5037,0)))*100
A15: 11 | B15: ED_JU | C15: Earnings Down / Juros Up | D15: Down | E15: Up | F15: 40513 | G15: 40575 | H15: 40575 | I15: 40574 | J15: =G15-F15 | K15: =COUNTIFS(Painel_diario!$A$2:$A$5037,">="&$F15,Painel_diario!$A$2:$A$5037,"<"&$H15) | L15: =COUNTIFS(Painel_diario!$A$2:$A$5037,">="&$F15,Painel_diario!$A$2:$A$5037,"<"&$H15,Painel_diario!$J$2:$J$5037,1) | M15: =COUNTIFS(Painel_diario!$A$2:$A$5037,">="&$F15,Painel_diario!$A$2:$A$5037,"<"&$H15,Painel_diario!$K$2:$K$5037,1) | N15: =EXP(SUMIFS(Painel_diario!$L$2:$L$5037,Painel_diario!$A$2:$A$5037,">="&$F15,Painel_diario!$A$2:$A$5037,"<"&$H15))-1 | O15: =IF(L15=0,"",EXP(SUMIFS(Painel_diario!$L$2:$L$5037,Painel_diario!$A$2:$A$5037,">="&$F15,Painel_diario!$A$2:$A$5037,"<"&$H15)*252/L15)-1) | P15: =EXP(SUMIFS(Painel_diario!$N$2:$N$5037,Painel_diario!$A$2:$A$5037,">="&$F15,Painel_diario!$A$2:$A$5037,"<"&$H15))-1 | Q15: =IF(M15=0,"",EXP(SUMIFS(Painel_diario!$N$2:$N$5037,Painel_diario!$A$2:$A$5037,">="&$F15,Painel_diario!$A$2:$A$5037,"<"&$H15)*252/M15)-1) | R15: =IF(L15=0,"",EXP(SUMIFS(Painel_diario!$P$2:$P$5037,Painel_diario!$A$2:$A$5037,">="&$F15,Painel_diario!$A$2:$A$5037,"<"&$H15)*252/L15)-1) | S15: =IF(L15=0,"",EXP((SUMIFS(Painel_diario!$L$2:$L$5037,Painel_diario!$A$2:$A$5037,">="&$F15,Painel_diario!$A$2:$A$5037,"<"&$H15)-SUMIFS(Painel_diario!$P$2:$P$5037,Painel_diario!$A$2:$A$5037,">="&$F15,Painel_diario!$A$2:$A$5037,"<"&$H15))*252/L15)-1) | T15: =IF(L15=0,"",EXP(SUMIFS(Painel_diario!$Q$2:$Q$5037,Painel_diario!$A$2:$A$5037,">="&$F15,Painel_diario!$A$2:$A$5037,"<"&$H15)*252/L15)-1) | U15: =(INDEX(Painel_diario!$S$2:$S$5037,MATCH($I15,Painel_diario!$A$2:$A$5037,0))-INDEX(Painel_diario!$S$2:$S$5037,MATCH($F15,Painel_diario!$A$2:$A$5037,0)))*100
A16: 12 | B16: EU_JU | C16: Earnings Up / Juros Up | D16: Up | E16: Up | F16: 40575 | G16: 40756 | H16: 40756 | I16: 40753 | J16: =G16-F16 | K16: =COUNTIFS(Painel_diario!$A$2:$A$5037,">="&$F16,Painel_diario!$A$2:$A$5037,"<"&$H16) | L16: =COUNTIFS(Painel_diario!$A$2:$A$5037,">="&$F16,Painel_diario!$A$2:$A$5037,"<"&$H16,Painel_diario!$J$2:$J$5037,1) | M16: =COUNTIFS(Painel_diario!$A$2:$A$5037,">="&$F16,Painel_diario!$A$2:$A$5037,"<"&$H16,Painel_diario!$K$2:$K$5037,1) | N16: =EXP(SUMIFS(Painel_diario!$L$2:$L$5037,Painel_diario!$A$2:$A$5037,">="&$F16,Painel_diario!$A$2:$A$5037,"<"&$H16))-1 | O16: =IF(L16=0,"",EXP(SUMIFS(Painel_diario!$L$2:$L$5037,Painel_diario!$A$2:$A$5037,">="&$F16,Painel_diario!$A$2:$A$5037,"<"&$H16)*252/L16)-1) | P16: =EXP(SUMIFS(Painel_diario!$N$2:$N$5037,Painel_diario!$A$2:$A$5037,">="&$F16,Painel_diario!$A$2:$A$5037,"<"&$H16))-1 | Q16: =IF(M16=0,"",EXP(SUMIFS(Painel_diario!$N$2:$N$5037,Painel_diario!$A$2:$A$5037,">="&$F16,Painel_diario!$A$2:$A$5037,"<"&$H16)*252/M16)-1) | R16: =IF(L16=0,"",EXP(SUMIFS(Painel_diario!$P$2:$P$5037,Painel_diario!$A$2:$A$5037,">="&$F16,Painel_diario!$A$2:$A$5037,"<"&$H16)*252/L16)-1) | S16: =IF(L16=0,"",EXP((SUMIFS(Painel_diario!$L$2:$L$5037,Painel_diario!$A$2:$A$5037,">="&$F16,Painel_diario!$A$2:$A$5037,"<"&$H16)-SUMIFS(Painel_diario!$P$2:$P$5037,Painel_diario!$A$2:$A$5037,">="&$F16,Painel_diario!$A$2:$A$5037,"<"&$H16))*252/L16)-1) | T16: =IF(L16=0,"",EXP(SUMIFS(Painel_diario!$Q$2:$Q$5037,Painel_diario!$A$2:$A$5037,">="&$F16,Painel_diario!$A$2:$A$5037,"<"&$H16)*252/L16)-1) | U16: =(INDEX(Painel_diario!$S$2:$S$5037,MATCH($I16,Painel_diario!$A$2:$A$5037,0))-INDEX(Painel_diario!$S$2:$S$5037,MATCH($F16,Painel_diario!$A$2:$A$5037,0)))*100
... A44: 40 | B44: ED_JD | C44: Earnings Down / Juros Down | D44: Down | E44: Down | F44: 45839 | G44: 45992 | H44: 45992 | I44: 45989 | J44: =G44-F44 | K44: =COUNTIFS(Painel_diario!$A$2:$A$5037,">="&$F44,Painel_diario!$A$2:$A$5037,"<"&$H44) | L44: =COUNTIFS(Painel_diario!$A$2:$A$5037,">="&$F44,Painel_diario!$A$2:$A$5037,"<"&$H44,Painel_diario!$J$2:$J$5037,1) | M44: =COUNTIFS(Painel_diario!$A$2:$A$5037,">="&$F44,Painel_diario!$A$2:$A$5037,"<"&$H44,Painel_diario!$K$2:$K$5037,1) | N44: =EXP(SUMIFS(Painel_diario!$L$2:$L$5037,Painel_diario!$A$2:$A$5037,">="&$F44,Painel_diario!$A$2:$A$5037,"<"&$H44))-1 | O44: =IF(L44=0,"",EXP(SUMIFS(Painel_diario!$L$2:$L$5037,Painel_diario!$A$2:$A$5037,">="&$F44,Painel_diario!$A$2:$A$5037,"<"&$H44)*252/L44)-1) | P44: =EXP(SUMIFS(Painel_diario!$N$2:$N$5037,Painel_diario!$A$2:$A$5037,">="&$F44,Painel_diario!$A$2:$A$5037,"<"&$H44))-1 | Q44: =IF(M44=0,"",EXP(SUMIFS(Painel_diario!$N$2:$N$5037,Painel_diario!$A$2:$A$5037,">="&$F44,Painel_diario!$A$2:$A$5037,"<"&$H44)*252/M44)-1) | R44: =IF(L44=0,"",EXP(SUMIFS(Painel_diario!$P$2:$P$5037,Painel_diario!$A$2:$A$5037,">="&$F44,Painel_diario!$A$2:$A$5037,"<"&$H44)*252/L44)-1) | S44: =IF(L44=0,"",EXP((SUMIFS(Painel_diario!$L$2:$L$5037,Painel_diario!$A$2:$A$5037,">="&$F44,Painel_diario!$A$2:$A$5037,"<"&$H44)-SUMIFS(Painel_diario!$P$2:$P$5037,Painel_diario!$A$2:$A$5037,">="&$F44,Painel_diario!$A$2:$A$5037,"<"&$H44))*252/L44)-1) | T44: =IF(L44=0,"",EXP(SUMIFS(Painel_diario!$Q$2:$Q$5037,Painel_diario!$A$2:$A$5037,">="&$F44,Painel_diario!$A$2:$A$5037,"<"&$H44)*252/L44)-1) | U44: =(INDEX(Painel_diario!$S$2:$S$5037,MATCH($I44,Painel_diario!$A$2:$A$5037,0))-INDEX(Painel_diario!$S$2:$S$5037,MATCH($F44,Painel_diario!$A$2:$A$5037,0)))*100
A45: 41 | B45: EU_JD | C45: Earnings Up / Juros Down | D45: Up | E45: Down | F45: 45992 | G45: 46246 | H45: 46247 | I45: 46246 | J45: =G45-F45 | K45: =COUNTIFS(Painel_diario!$A$2:$A$5037,">="&$F45,Painel_diario!$A$2:$A$5037,"<"&$H45) | L45: =COUNTIFS(Painel_diario!$A$2:$A$5037,">="&$F45,Painel_diario!$A$2:$A$5037,"<"&$H45,Painel_diario!$J$2:$J$5037,1) | M45: =COUNTIFS(Painel_diario!$A$2:$A$5037,">="&$F45,Painel_diario!$A$2:$A$5037,"<"&$H45,Painel_diario!$K$2:$K$5037,1) | N45: =EXP(SUMIFS(Painel_diario!$L$2:$L$5037,Painel_diario!$A$2:$A$5037,">="&$F45,Painel_diario!$A$2:$A$5037,"<"&$H45))-1 | O45: =IF(L45=0,"",EXP(SUMIFS(Painel_diario!$L$2:$L$5037,Painel_diario!$A$2:$A$5037,">="&$F45,Painel_diario!$A$2:$A$5037,"<"&$H45)*252/L45)-1) | P45: =EXP(SUMIFS(Painel_diario!$N$2:$N$5037,Painel_diario!$A$2:$A$5037,">="&$F45,Painel_diario!$A$2:$A$5037,"<"&$H45))-1 | Q45: =IF(M45=0,"",EXP(SUMIFS(Painel_diario!$N$2:$N$5037,Painel_diario!$A$2:$A$5037,">="&$F45,Painel_diario!$A$2:$A$5037,"<"&$H45)*252/M45)-1) | R45: =IF(L45=0,"",EXP(SUMIFS(Painel_diario!$P$2:$P$5037,Painel_diario!$A$2:$A$5037,">="&$F45,Painel_diario!$A$2:$A$5037,"<"&$H45)*252/L45)-1) | S45: =IF(L45=0,"",EXP((SUMIFS(Painel_diario!$L$2:$L$5037,Painel_diario!$A$2:$A$5037,">="&$F45,Painel_diario!$A$2:$A$5037,"<"&$H45)-SUMIFS(Painel_diario!$P$2:$P$5037,Painel_diario!$A$2:$A$5037,">="&$F45,Painel_diario!$A$2:$A$5037,"<"&$H45))*252/L45)-1) | T45: =IF(L45=0,"",EXP(SUMIFS(Painel_diario!$Q$2:$Q$5037,Painel_diario!$A$2:$A$5037,">="&$F45,Painel_diario!$A$2:$A$5037,"<"&$H45)*252/L45)-1) | U45: =(INDEX(Painel_diario!$S$2:$S$5037,MATCH($I45,Painel_diario!$A$2:$A$5037,0))-INDEX(Painel_diario!$S$2:$S$5037,MATCH($F45,Painel_diario!$A$2:$A$5037,0)))*100 | V45: Sim
A47: Retorno anualizado usa capitalizacao log com 252 pregoes. O real desconta o IPCA do mes alocado por intervalo. USDBRL positivo = real se desvalorizando.
A48: Swap 360d (bps) = variacao do nivel da taxa entre o primeiro e o ultimo pregao do episodio.
A49: O episodio corrente termina em 12/08/2026 e nao tem IPCA de agosto, por isso os intervalos com IPCA sao menores que os intervalos totais.

Sheet Ep_por_quadrante
A1: Episodios por quadrante
A2: Mesmo formato das tabelas do report da XP: primeiro sinal, fim e duracao, com o desempenho do Ibovespa em cada janela.
A4: Earnings Up / Juros Down
A5: Primeiro sinal | B5: Fim | C5: Duracao (dias) | D5: Ibov total nominal | E5: Ibov anual real | F5: Ibov anual sobre CDI
A6: =Episodios!F5 | B6: =IF(Episodios!V5="Sim","Atual",Episodios!G5) | C6: =Episodios!J5 | D6: =Episodios!N5 | E6: =Episodios!Q5 | F6: =Episodios!S5
A7: =Episodios!F7 | B7: =IF(Episodios!V7="Sim","Atual",Episodios!G7) | C7: =Episodios!J7 | D7: =Episodios!N7 | E7: =Episodios!Q7 | F7: =Episodios!S7
A8: =Episodios!F11 | B8: =IF(Episodios!V11="Sim","Atual",Episodios!G11) | C8: =Episodios!J11 | D8: =Episodios!N11 | E8: =Episodios!Q11 | F8: =Episodios!S11
A9: =Episodios!F13 | B9: =IF(Episodios!V13="Sim","Atual",Episodios!G13) | C9: =Episodios!J13 | D9: =Episodios!N13 | E9: =Episodios!Q13 | F9: =Episodios!S13
A10: =Episodios!F25 | B10: =IF(Episodios!V25="Sim","Atual",Episodios!G25) | C10: =Episodios!J25 | D10: =Episodios!N25 | E10: =Episodios!Q25 | F10: =Episodios!S25
A11: =Episodios!F27 | B11: =IF(Episodios!V27="Sim","Atual",Episodios!G27) | C11: =Episodios!J27 | D11: =Episodios!N27 | E11: =Episodios!Q27 | F11: =Episodios!S27
A12: =Episodios!F29 | B12: =IF(Episodios!V29="Sim","Atual",Episodios!G29) | C12: =Episodios!J29 | D12: =Episodios!N29 | E12: =Episodios!Q29 | F12: =Episodios!S29
A13: =Episodios!F31 | B13: =IF(Episodios!V31="Sim","Atual",Episodios!G31) | C13: =Episodios!J31 | D13: =Episodios!N31 | E13: =Episodios!Q31 | F13: =Episodios!S31
A14: =Episodios!F37 | B14: =IF(Episodios!V37="Sim","Atual",Episodios!G37) | C14: =Episodios!J37 | D14: =Episodios!N37 | E14: =Episodios!Q37 | F14: =Episodios!S37
A15: =Episodios!F39 | B15: =IF(Episodios!V39="Sim","Atual",Episodios!G39) | C15: =Episodios!J39 | D15: =Episodios!N39 | E15: =Episodios!Q39 | F15: =Episodios!S39
A16: =Episodios!F43 | B16: =IF(Episodios!V43="Sim","Atual",Episodios!G43) | C16: =Episodios!J43 | D16: =Episodios!N43 | E16: =Episodios!Q43 | F16: =Episodios!S43
A17: =Episodios!F45 | B17: =IF(Episodios!V45="Sim","Atual",Episodios!G45) | C17: =Episodios!J45 | D17: =Episodios!N45 | E17: =Episodios!Q45 | F17: =Episodios!S45
A18: Mediana | C18: =MEDIAN(C6:C17) | E18: =MEDIAN(E6:E17)
A19: Media ponderada por dias | E19: =Resumo_regimes!I5 | F19: =Resumo_regimes!J5
A20: Taxa de acerto (episodios com retorno real positivo) | E20: =Resumo_regimes!M5
A23: Earnings Up / Juros Up
A24: Primeiro sinal | B24: Fim | C24: Duracao (dias) | D24: Ibov total nominal | E24: Ibov anual real | F24: Ibov anual sobre CDI
A25: =Episodios!F8 | B25: =IF(Episodios!V8="Sim","Atual",Episodios!G8) | C25: =Episodios!J8 | D25: =Episodios!N8 | E25: =Episodios!Q8 | F25: =Episodios!S8
A26: =Episodios!F10 | B26: =IF(Episodios!V10="Sim","Atual",Episodios!G10) | C26: =Episodios!J10 | D26: =Episodios!N10 | E26: =Episodios!Q10 | F26: =Episodios!S10
A27: =Episodios!F14 | B27: =IF(Episodios!V14="Sim","Atual",Episodios!G14) | C27: =Episodios!J14 | D27: =Episodios!N14 | E27: =Episodios!Q14 | F27: =Episodios!S14
A28: =Episodios!F16 | B28: =IF(Episodios!V16="Sim","Atual",Episodios!G16) | C28: =Episodios!J16 | D28: =Episodios!N16 | E28: =Episodios!Q16 | F28: =Episodios!S16
A29: =Episodios!F20 | B29: =IF(Episodios!V20="Sim","Atual",Episodios!G20) | C29: =Episodios!J20 | D29: =Episodios!N20 | E29: =Episodios!Q20 | F29: =Episodios!S20
A30: =Episodios!F22 | B30: =IF(Episodios!V22="Sim","Atual",Episodios!G22) | C30: =Episodios!J22 | D30: =Episodios!N22 | E30: =Episodios!Q22 | F30: =Episodios!S22
A31: =Episodios!F28 | B31: =IF(Episodios!V28="Sim","Atual",Episodios!G28) | C31: =Episodios!J28 | D31: =Episodios!N28 | E31: =Episodios!Q28 | F31: =Episodios!S28
A32: =Episodios!F32 | B32: =IF(Episodios!V32="Sim","Atual",Episodios!G32) | C32: =Episodios!J32 | D32: =Episodios!N32 | E32: =Episodios!Q32 | F32: =Episodios!S32
A33: =Episodios!F34 | B33: =IF(Episodios!V34="Sim","Atual",Episodios!G34) | C33: =Episodios!J34 | D33: =Episodios!N34 | E33: =Episodios!Q34 | F33: =Episodios!S34
A34: =Episodios!F40 | B34: =IF(Episodios!V40="Sim","Atual",Episodios!G40) | C34: =Episodios!J40 | D34: =Episodios!N40 | E34: =Episodios!Q40 | F34: =Episodios!S40
A35: =Episodios!F42 | B35: =IF(Episodios!V42="Sim","Atual",Episodios!G42) | C35: =Episodios!J42 | D35: =Episodios!N42 | E35: =Episodios!Q42 | F35: =Episodios!S42
A36: Mediana | C36: =MEDIAN(C25:C35) | E36: =MEDIAN(E25:E35)
A37: Media ponderada por dias | E37: =Resumo_regimes!I6 | F37: =Resumo_regimes!J6
A38: Taxa de acerto (episodios com retorno real positivo) | E38: =Resumo_regimes!M6
A41: Earnings Down / Juros Down
A42: Primeiro sinal | B42: Fim | C42: Duracao (dias) | D42: Ibov total nominal | E42: Ibov anual real | F42: Ibov anual sobre CDI
A43: =Episodios!F6 | B43: =IF(Episodios!V6="Sim","Atual",Episodios!G6) | C43: =Episodios!J6 | D43: =Episodios!N6 | E43: =Episodios!Q6 | F43: =Episodios!S6
A44: =Episodios!F12 | B44: =IF(Episodios!V12="Sim","Atual",Episodios!G12) | C44: =Episodios!J12 | D44: =Episodios!N12 | E44: =Episodios!Q12 | F44: =Episodios!S12
A45: =Episodios!F18 | B45: =IF(Episodios!V18="Sim","Atual",Episodios!G18) | C45: =Episodios!J18 | D45: =Episodios!N18 | E45: =Episodios!Q18 | F45: =Episodios!S18
...

Sheet Classes_ativos
A1: Desempenho de classes de ativos em cada episodio
A2: Formato da tabela do report da XP. Nao ha SMLL, IMA-B nem cestas de fatores nos dados do projeto, entao as linhas disponiveis sao Ibovespa, CDI, USDBRL e o nivel do swap.
A4: Earnings Up / Juros Down
A5: Inicio | B5: =Episodios!F5 | C5: =Episodios!F7 | D5: =Episodios!F11 | E5: =Episodios!F13 | F5: =Episodios!F25 | G5: =Episodios!F27 | H5: =Episodios!F29 | I5: =Episodios!F31 | J5: =Episodios!F37 | K5: =Episodios!F39 | L5: =Episodios!F43 | M5: =Episodios!F45 | N5: Media ponderada | O5: Taxa de acerto
A6: Fim | B6: =IF(Episodios!V5="Sim","Atual",Episodios!G5) | C6: =IF(Episodios!V7="Sim","Atual",Episodios!G7) | D6: =IF(Episodios!V11="Sim","Atual",Episodios!G11) | E6: =IF(Episodios!V13="Sim","Atual",Episodios!G13) | F6: =IF(Episodios!V25="Sim","Atual",Episodios!G25) | G6: =IF(Episodios!V27="Sim","Atual",Episodios!G27) | H6: =IF(Episodios!V29="Sim","Atual",Episodios!G29) | I6: =IF(Episodios!V31="Sim","Atual",Episodios!G31) | J6: =IF(Episodios!V37="Sim","Atual",Episodios!G37) | K6: =IF(Episodios!V39="Sim","Atual",Episodios!G39) | L6: =IF(Episodios!V43="Sim","Atual",Episodios!G43) | M6: =IF(Episodios!V45="Sim","Atual",Episodios!G45)
A7: Duracao (dias) | B7: =Episodios!J5 | C7: =Episodios!J7 | D7: =Episodios!J11 | E7: =Episodios!J13 | F7: =Episodios!J25 | G7: =Episodios!J27 | H7: =Episodios!J29 | I7: =Episodios!J31 | J7: =Episodios!J37 | K7: =Episodios!J39 | L7: =Episodios!J43 | M7: =Episodios!J45
A8: Ibovespa nominal anualizado | B8: =Episodios!O5 | C8: =Episodios!O7 | D8: =Episodios!O11 | E8: =Episodios!O13 | F8: =Episodios!O25 | G8: =Episodios!O27 | H8: =Episodios!O29 | I8: =Episodios!O31 | J8: =Episodios!O37 | K8: =Episodios!O39 | L8: =Episodios!O43 | M8: =Episodios!O45 | N8: =Resumo_regimes!H5 | O8: =COUNTIF(B8:M8,">0")/COUNT(B8:M8)
A9: Ibovespa real anualizado | B9: =Episodios!Q5 | C9: =Episodios!Q7 | D9: =Episodios!Q11 | E9: =Episodios!Q13 | F9: =Episodios!Q25 | G9: =Episodios!Q27 | H9: =Episodios!Q29 | I9: =Episodios!Q31 | J9: =Episodios!Q37 | K9: =Episodios!Q39 | L9: =Episodios!Q43 | M9: =Episodios!Q45 | N9: =Resumo_regimes!I5 | O9: =COUNTIF(B9:M9,">0")/COUNT(B9:M9)
A10: Ibovespa sobre o CDI, anualizado | B10: =Episodios!S5 | C10: =Episodios!S7 | D10: =Episodios!S11 | E10: =Episodios!S13 | F10: =Episodios!S25 | G10: =Episodios!S27 | H10: =Episodios!S29 | I10: =Episodios!S31 | J10: =Episodios!S37 | K10: =Episodios!S39 | L10: =Episodios!S43 | M10: =Episodios!S45 | N10: =Resumo_regimes!J5 | O10: =COUNTIF(B10:M10,">0")/COUNT(B10:M10)
A11: CDI anualizado | B11: =Episodios!R5 | C11: =Episodios!R7 | D11: =Episodios!R11 | E11: =Episodios!R13 | F11: =Episodios!R25 | G11: =Episodios!R27 | H11: =Episodios!R29 | I11: =Episodios!R31 | J11: =Episodios!R37 | K11: =Episodios!R39 | L11: =Episodios!R43 | M11: =Episodios!R45 | N11: =SUMPRODUCT(B11:M11,$B$7:$M$7)/SUM($B$7:$M$7) | O11: =COUNTIF(B11:M11,">0")/COUNT(B11:M11)
A12: USDBRL anualizado | B12: =Episodios!T5 | C12: =Episodios!T7 | D12: =Episodios!T11 | E12: =Episodios!T13 | F12: =Episodios!T25 | G12: =Episodios!T27 | H12: =Episodios!T29 | I12: =Episodios!T31 | J12: =Episodios!T37 | K12: =Episodios!T39 | L12: =Episodios!T43 | M12: =Episodios!T45 | N12: =SUMPRODUCT(B12:M12,$B$7:$M$7)/SUM($B$7:$M$7) | O12: =COUNTIF(B12:M12,">0")/COUNT(B12:M12)
A13: Swap 360d, variacao (bps) | B13: =Episodios!U5 | C13: =Episodios!U7 | D13: =Episodios!U11 | E13: =Episodios!U13 | F13: =Episodios!U25 | G13: =Episodios!U27 | H13: =Episodios!U29 | I13: =Episodios!U31 | J13: =Episodios!U37 | K13: =Episodios!U39 | L13: =Episodios!U43 | M13: =Episodios!U45 | N13: =SUMPRODUCT(B13:M13,$B$7:$M$7)/SUM($B$7:$M$7) | O13: =COUNTIF(B13:M13,">0")/COUNT(B13:M13)
A17: Earnings Up / Juros Up
A18: Inicio | B18: =Episodios!F8 | C18: =Episodios!F10 | D18: =Episodios!F14 | E18: =Episodios!F16 | F18: =Episodios!F20 | G18: =Episodios!F22 | H18: =Episodios!F28 | I18: =Episodios!F32 | J18: =Episodios!F34 | K18: =Episodios!F40 | L18: =Episodios!F42 | M18: Media ponderada | N18: Taxa de acerto
A19: Fim | B19: =IF(Episodios!V8="Sim","Atual",Episodios!G8) | C19: =IF(Episodios!V10="Sim","Atual",Episodios!G10) | D19: =IF(Episodios!V14="Sim","Atual",Episodios!G14) | E19: =IF(Episodios!V16="Sim","Atual",Episodios!G16) | F19: =IF(Episodios!V20="Sim","Atual",Episodios!G20) | G19: =IF(Episodios!V22="Sim","Atual",Episodios!G22) | H19: =IF(Episodios!V28="Sim","Atual",Episodios!G28) | I19: =IF(Episodios!V32="Sim","Atual",Episodios!G32) | J19: =IF(Episodios!V34="Sim","Atual",Episodios!G34) | K19: =IF(Episodios!V40="Sim","Atual",Episodios!G40) | L19: =IF(Episodios!V42="Sim","Atual",Episodios!G42)
A20: Duracao (dias) | B20: =Episodios!J8 | C20: =Episodios!J10 | D20: =Episodios!J14 | E20: =Episodios!J16 | F20: =Episodios!J20 | G20: =Episodios!J22 | H20: =Episodios!J28 | I20: =Episodios!J32 | J20: =Episodios!J34 | K20: =Episodios!J40 | L20: =Episodios!J42
A21: Ibovespa nominal anualizado | B21: =Episodios!O8 | C21: =Episodios!O10 | D21: =Episodios!O14 | E21: =Episodios!O16 | F21: =Episodios!O20 | G21: =Episodios!O22 | H21: =Episodios!O28 | I21: =Episodios!O32 | J21: =Episodios!O34 | K21: =Episodios!O40 | L21: =Episodios!O42 | M21: =Resumo_regimes!H6 | N21: =COUNTIF(B21:L21,">0")/COUNT(B21:L21)
A22: Ibovespa real anualizado | B22: =Episodios!Q8 | C22: =Episodios!Q10 | D22: =Episodios!Q14 | E22: =Episodios!Q16 | F22: =Episodios!Q20 | G22: =Episodios!Q22 | H22: =Episodios!Q28 | I22: =Episodios!Q32 | J22: =Episodios!Q34 | K22: =Episodios!Q40 | L22: =Episodios!Q42 | M22: =Resumo_regimes!I6 | N22: =COUNTIF(B22:L22,">0")/COUNT(B22:L22)
A23: Ibovespa sobre o CDI, anualizado | B23: =Episodios!S8 | C23: =Episodios!S10 | D23: =Episodios!S14 | E23: =Episodios!S16 | F23: =Episodios!S20 | G23: =Episodios!S22 | H23: =Episodios!S28 | I23: =Episodios!S32 | J23: =Episodios!S34 | K23: =Episodios!S40 | L23: =Episodios!S42 | M23: =Resumo_regimes!J6 | N23: =COUNTIF(B23:L23,">0")/COUNT(B23:L23)
A24: CDI anualizado | B24: =Episodios!R8 | C24: =Episodios!R10 | D24: =Episodios!R14 | E24: =Episodios!R16 | F24: =Episodios!R20 | G24: =Episodios!R22 | H24: =Episodios!R28 | I24: =Episodios!R32 | J24: =Episodios!R34 | K24: =Episodios!R40 | L24: =Episodios!R42 | M24: =SUMPRODUCT(B24:L24,$B$20:$L$20)/SUM($B$20:$L$20) | N24: =COUNTIF(B24:L24,">0")/COUNT(B24:L24)
A25: USDBRL anualizado | B25: =Episodios!T8 | C25: =Episodios!T10 | D25: =Episodios!T14 | E25: =Episodios!T16 | F25: =Episodios!T20 | G25: =Episodios!T22 | H25: =Episodios!T28 | I25: =Episodios!T32 | J25: =Episodios!T34 | K25: =Episodios!T40 | L25: =Episodios!T42 | M25: =SUMPRODUCT(B25:L25,$B$20:$L$20)/SUM($B$20:$L$20) | N25: =COUNTIF(B25:L25,">0")/COUNT(B25:L25)
A26: Swap 360d, variacao (bps) | B26: =Episodios!U8 | C26: =Episodios!U10 | D26: =Episodios!U14 | E26: =Episodios!U16 | F26: =Episodios!U20 | G26: =Episodios!U22 | H26: =Episodios!U28 | I26: =Episodios!U32 | J26: =Episodios!U34 | K26: =Episodios!U40 | L26: =Episodios!U42 | M26: =SUMPRODUCT(B26:L26,$B$20:$L$20)/SUM($B$20:$L$20) | N26: =COUNTIF(B26:L26,">0")/COUNT(B26:L26)
A30: Earnings Down / Juros Down
A31: Inicio | B31: =Episodios!F6 | C31: =Episodios!F12 | D31: =Episodios!F18 | E31: =Episodios!F24 | F31: =Episodios!F26 | G31: =Episodios!F30 | H31: =Episodios!F36 | I31: =Episodios!F38 | J31: =Episodios!F44 | K31: Media ponderada | L31: Taxa de acerto
A32: Fim | B32: =IF(Episodios!V6="Sim","Atual",Episodios!G6) | C32: =IF(Episodios!V12="Sim","Atual",Episodios!G12) | D32: =IF(Episodios!V18="Sim","Atual",Episodios!G18) | E32: =IF(Episodios!V24="Sim","Atual",Episodios!G24) | F32: =IF(Episodios!V26="Sim","Atual",Episodios!G26) | G32: =IF(Episodios!V30="Sim","Atual",Episodios!G30) | H32: =IF(Episodios!V36="Sim","Atual",Episodios!G36) | I32: =IF(Episodios!V38="Sim","Atual",Episodios!G38) | J32: =IF(Episodios!V44="Sim","Atual",Episodios!G44)
A33: Duracao (dias) | B33: =Episodios!J6 | C33: =Episodios!J12 | D33: =Episodios!J18 | E33: =Episodios!J24 | F33: =Episodios!J26 | G33: =Episodios!J30 | H33: =Episodios!J36 | I33: =Episodios!J38 | J33: =Episodios!J44
A34: Ibovespa nominal anualizado | B34: =Episodios!O6 | C34: =Episodios!O12 | D34: =Episodios!O18 | E34: =Episodios!O24 | F34: =Episodios!O26 | G34: =Episodios!O30 | H34: =Episodios!O36 | I34: =Episodios!O38 | J34: =Episodios!O44 | K34: =Resumo_regimes!H7 | L34: =COUNTIF(B34:J34,">0")/COUNT(B34:J34)
A35: Ibovespa real anualizado | B35: =Episodios!Q6 | C35: =Episodios!Q12 | D35: =Episodios!Q18 | E35: =Episodios!Q24 | F35: =Episodios!Q26 | G35: =Episodios!Q30 | H35: =Episodios!Q36 | I35: =Episodios!Q38 | J35: =Episodios!Q44 | K35: =Resumo_regimes!I7 | L35: =COUNTIF(B35:J35,">0")/COUNT(B35:J35)
A36: Ibovespa sobre o CDI, anualizado | B36: =Episodios!S6 | C36: =Episodios!S12 | D36: =Episodios!S18 | E36: =Episodios!S24 | F36: =Episodios!S26 | G36: =Episodios!S30 | H36: =Episodios!S36 | I36: =Episodios!S38 | J36: =Episodios!S44 | K36: =Resumo_regimes!J7 | L36: =COUNTIF(B36:J36,">0")/COUNT(B36:J36)
A37: CDI anualizado | B37: =Episodios!R6 | C37: =Episodios!R12 | D37: =Episodios!R18 | E37: =Episodios!R24 | F37: =Episodios!R26 | G37: =Episodios!R30 | H37: =Episodios!R36 | I37: =Episodios!R38 | J37: =Episodios!R44 | K37: =SUMPRODUCT(B37:J37,$B$33:$J$33)/SUM($B$33:$J$33) | L37: =COUNTIF(B37:J37,">0")/COUNT(B37:J37)
A38: USDBRL anualizado | B38: =Episodios!T6 | C38: =Episodios!T12 | D38: =Episodios!T18 | E38: =Episodios!T24 | F38: =Episodios!T26 | G38: =Episodios!T30 | H38: =Episodios!T36 | I38: =Episodios!T38 | J38: =Episodios!T44 | K38: =SUMPRODUCT(B38:J38,$B$33:$J$33)/SUM($B$33:$J$33) | L38: =COUNTIF(B38:J38,">0")/COUNT(B38:J38)
A39: Swap 360d, variacao (bps) | B39: =Episodios!U6 | C39: =Episodios!U12 | D39: =Episodios!U18 | E39: =Episodios!U24 | F39: =Episodios!U26 | G39: =Episodios!U30 | H39: =Episodios!U36 | I39: =Episodios!U38 | J39: =Episodios!U44 | K39: =SUMPRODUCT(B39:J39,$B$33:$J$33)/SUM($B$33:$J$33) | L39: =COUNTIF(B39:J39,">0")/COUNT(B39:J39)
A43: Earnings Down / Juros Up
A44: Inicio | B44: =Episodios!F9 | C44: =Episodios!F15 | D44: =Episodios!F17 | E44: =Episodios!F19 | F44: =Episodios!F21 | G44: =Episodios!F23 | H44: =Episodios!F33 | I44: =Episodios!F35 | J44: =Episodios!F41 | K44: Media ponderada | L44: Taxa de acerto
A45: Fim | B45: =IF(Episodios!V9="Sim","Atual",Episodios!G9) | C45: =IF(Episodios!V15="Sim","Atual",Episodios!G15) | D45: =IF(Episodios!V17="Sim","Atual",Episodios!G17) | E45: =IF(Episodios!V19="Sim","Atual",Episodios!G19) | F45: =IF(Episodios!V21="Sim","Atual",Episodios!G21) | G45: =IF(Episodios!V23="Sim","Atual",Episodios!G23) | H45: =IF(Episodios!V33="Sim","Atual",Episodios!G33) | I45: =IF(Episodios!V35="Sim","Atual",Episodios!G35) | J45: =IF(Episodios!V41="Sim","Atual",Episodios!G41)
A46: Duracao (dias) | B46: =Episodios!J9 | C46: =Episodios!J15 | D46: =Episodios!J17 | E46: =Episodios!J19 | F46: =Episodios!J21 | G46: =Episodios!J23 | H46: =Episodios!J33 | I46: =Episodios!J35 | J46: =Episodios!J41
A47: Ibovespa nominal anualizado | B47: =Episodios!O9 | C47: =Episodios!O15 | D47: =Episodios!O17 | E47: =Episodios!O19 | F47: =Episodios!O21 | G47: =Episodios!O23 | H47: =Episodios!O33 | I47: =Episodios!O35 | J47: =Episodios!O41 | K47: =Resumo_regimes!H8 | L47: =COUNTIF(B47:J47,">0")/COUNT(B47:J47)
A48: Ibovespa real anualizado | B48: =Episodios!Q9 | C48: =Episodios!Q15 | D48: =Episodios!Q17 | E48: =Episodios!Q19 | F48: =Episodios!Q21 | G48: =Episodios!Q23 | H48: =Episodios!Q33 | I48: =Episodios!Q35 | J48: =Episodios!Q41 | K48: =Resumo_regimes!I8 | L48: =COUNTIF(B48:J48,">0")/COUNT(B48:J48)
A49: Ibovespa sobre o CDI, anualizado | B49: =Episodios!S9 | C49: =Episodios!S15 | D49: =Episodios!S17 | E49: =Episodios!S19 | F49: =Episodios!S21 | G49: =Episodios!S23 | H49: =Episodios!S33 | I49: =Episodios!S35 | J49: =Episodios!S41 | K49: =Resumo_regimes!J8 | L49: =COUNTIF(B49:J49,">0")/COUNT(B49:J49)
A50: CDI anualizado | B50: =Episodios!R9 | C50: =Episodios!R15 | D50: =Episodios!R17 | E50: =Episodios!R19 | F50: =Episodios!R21 | G50: =Episodios!R23 | H50: =Episodios!R33 | I50: =Episodios!R35 | J50: =Episodios!R41 | K50: =SUMPRODUCT(B50:J50,$B$46:$J$46)/SUM($B$46:$J$46) | L50: =COUNTIF(B50:J50,">0")/COUNT(B50:J50)
...

Sheet Transicoes
A1: Matriz de transicao entre quadrantes
A2: Com que frequencia, historicamente, cada quadrante foi seguido por cada outro. Equivalente ao diagrama de transicao do report da XP.
A4: De \ Para | B4: Earnings Up / Juros Down | C4: Earnings Up / Juros Up | D4: Earnings Down / Juros Down | E4: Earnings Down / Juros Up | F4: Total de transicoes
A5: Earnings Up / Juros Down | B5: 0 | C5: 0.45454545 | D5: 0.54545455 | E5: 0 | F5: 11
A6: Earnings Up / Juros Up | B6: 0.27272727 | C6: 0 | D6: 0 | E6: 0.72727273 | F6: 11
A7: Earnings Down / Juros Down | B7: 0.88888889 | C7: 0 | D7: 0 | E7: 0.11111111 | F7: 9
A8: Earnings Down / Juros Up | B8: 0 | C8: 0.66666667 | D8: 0.33333333 | E8: 0 | F8: 9
A10: Contagens absolutas
A11: De \ Para | B11: Earnings Up / Juros Down | C11: Earnings Up / Juros Up | D11: Earnings Down / Juros Down | E11: Earnings Down / Juros Up | F11: Total
A12: Earnings Up / Juros Down | B12: 0 | C12: 5 | D12: 6 | E12: 0 | F12: =SUM(B12:E12)
A13: Earnings Up / Juros Up | B13: 3 | C13: 0 | D13: 0 | E13: 8 | F13: =SUM(B13:E13)
A14: Earnings Down / Juros Down | B14: 8 | C14: 0 | D14: 0 | E14: 1 | F14: =SUM(B14:E14)
A15: Earnings Down / Juros Up | B15: 0 | C15: 6 | D15: 3 | E15: 0 | F15: =SUM(B15:E15)
A17: Transicoes contadas sobre 41 episodios, portanto 40 transicoes. A diagonal e zero por construcao: um episodio so termina quando o quadrante muda.
A18: Uma mudanca de quadrante pode vir do lado de earnings ou do lado de juros, nunca dos dois no mesmo dia, exceto por coincidencia de datas.

Sheet Acumulado_por_regime
A1: Desempenho acumulado do Ibovespa dentro de cada regime
A2: Cada curva acumula apenas os retornos dos dias pertencentes ao seu quadrante e fica horizontal nos demais dias. Nao representa uma carteira investida continuamente: mostra a contribuicao historica do Ibovespa nos intervalos de cada regime.
A4: Data | B4: Earnings Up / Juros Down | C4: Earnings Up / Juros Up | D4: Earnings Down / Juros Down | E4: Earnings Down / Juros Up
A5: 38810 | B5: 0 | C5: 0 | D5: 0 | E5: 0
A6: 38811 | B6: =(1+B5)*IF(AND(Painel_diario!$H2="EU_JD",Painel_diario!$J2=1),EXP(Painel_diario!$L2),1)-1 | C6: =(1+C5)*IF(AND(Painel_diario!$H2="EU_JU",Painel_diario!$J2=1),EXP(Painel_diario!$L2),1)-1 | D6: =(1+D5)*IF(AND(Painel_diario!$H2="ED_JD",Painel_diario!$J2=1),EXP(Painel_diario!$L2),1)-1 | E6: =(1+E5)*IF(AND(Painel_diario!$H2="ED_JU",Painel_diario!$J2=1),EXP(Painel_diario!$L2),1)-1
A7: 38812 | B7: =(1+B6)*IF(AND(Painel_diario!$H3="EU_JD",Painel_diario!$J3=1),EXP(Painel_diario!$L3),1)-1 | C7: =(1+C6)*IF(AND(Painel_diario!$H3="EU_JU",Painel_diario!$J3=1),EXP(Painel_diario!$L3),1)-1 | D7: =(1+D6)*IF(AND(Painel_diario!$H3="ED_JD",Painel_diario!$J3=1),EXP(Painel_diario!$L3),1)-1 | E7: =(1+E6)*IF(AND(Painel_diario!$H3="ED_JU",Painel_diario!$J3=1),EXP(Painel_diario!$L3),1)-1
A8: 38813 | B8: =(1+B7)*IF(AND(Painel_diario!$H4="EU_JD",Painel_diario!$J4=1),EXP(Painel_diario!$L4),1)-1 | C8: =(1+C7)*IF(AND(Painel_diario!$H4="EU_JU",Painel_diario!$J4=1),EXP(Painel_diario!$L4),1)-1 | D8: =(1+D7)*IF(AND(Painel_diario!$H4="ED_JD",Painel_diario!$J4=1),EXP(Painel_diario!$L4),1)-1 | E8: =(1+E7)*IF(AND(Painel_diario!$H4="ED_JU",Painel_diario!$J4=1),EXP(Painel_diario!$L4),1)-1
A9: 38814 | B9: =(1+B8)*IF(AND(Painel_diario!$H5="EU_JD",Painel_diario!$J5=1),EXP(Painel_diario!$L5),1)-1 | C9: =(1+C8)*IF(AND(Painel_diario!$H5="EU_JU",Painel_diario!$J5=1),EXP(Painel_diario!$L5),1)-1 | D9: =(1+D8)*IF(AND(Painel_diario!$H5="ED_JD",Painel_diario!$J5=1),EXP(Painel_diario!$L5),1)-1 | E9: =(1+E8)*IF(AND(Painel_diario!$H5="ED_JU",Painel_diario!$J5=1),EXP(Painel_diario!$L5),1)-1
A10: 38817 | B10: =(1+B9)*IF(AND(Painel_diario!$H6="EU_JD",Painel_diario!$J6=1),EXP(Painel_diario!$L6),1)-1 | C10: =(1+C9)*IF(AND(Painel_diario!$H6="EU_JU",Painel_diario!$J6=1),EXP(Painel_diario!$L6),1)-1 | D10: =(1+D9)*IF(AND(Painel_diario!$H6="ED_JD",Painel_diario!$J6=1),EXP(Painel_diario!$L6),1)-1 | E10: =(1+E9)*IF(AND(Painel_diario!$H6="ED_JU",Painel_diario!$J6=1),EXP(Painel_diario!$L6),1)-1
A11: 38818 | B11: =(1+B10)*IF(AND(Painel_diario!$H7="EU_JD",Painel_diario!$J7=1),EXP(Painel_diario!$L7),1)-1 | C11: =(1+C10)*IF(AND(Painel_diario!$H7="EU_JU",Painel_diario!$J7=1),EXP(Painel_diario!$L7),1)-1 | D11: =(1+D10)*IF(AND(Painel_diario!$H7="ED_JD",Painel_diario!$J7=1),EXP(Painel_diario!$L7),1)-1 | E11: =(1+E10)*IF(AND(Painel_diario!$H7="ED_JU",Painel_diario!$J7=1),EXP(Painel_diario!$L7),1)-1
A12: 38819 | B12: =(1+B11)*IF(AND(Painel_diario!$H8="EU_JD",Painel_diario!$J8=1),EXP(Painel_diario!$L8),1)-1 | C12: =(1+C11)*IF(AND(Painel_diario!$H8="EU_JU",Painel_diario!$J8=1),EXP(Painel_diario!$L8),1)-1 | D12: =(1+D11)*IF(AND(Painel_diario!$H8="ED_JD",Painel_diario!$J8=1),EXP(Painel_diario!$L8),1)-1 | E12: =(1+E11)*IF(AND(Painel_diario!$H8="ED_JU",Painel_diario!$J8=1),EXP(Painel_diario!$L8),1)-1
A13: 38820 | B13: =(1+B12)*IF(AND(Painel_diario!$H9="EU_JD",Painel_diario!$J9=1),EXP(Painel_diario!$L9),1)-1 | C13: =(1+C12)*IF(AND(Painel_diario!$H9="EU_JU",Painel_diario!$J9=1),EXP(Painel_diario!$L9),1)-1 | D13: =(1+D12)*IF(AND(Painel_diario!$H9="ED_JD",Painel_diario!$J9=1),EXP(Painel_diario!$L9),1)-1 | E13: =(1+E12)*IF(AND(Painel_diario!$H9="ED_JU",Painel_diario!$J9=1),EXP(Painel_diario!$L9),1)-1
A14: 38824 | B14: =(1+B13)*IF(AND(Painel_diario!$H10="EU_JD",Painel_diario!$J10=1),EXP(Painel_diario!$L10),1)-1 | C14: =(1+C13)*IF(AND(Painel_diario!$H10="EU_JU",Painel_diario!$J10=1),EXP(Painel_diario!$L10),1)-1 | D14: =(1+D13)*IF(AND(Painel_diario!$H10="ED_JD",Painel_diario!$J10=1),EXP(Painel_diario!$L10),1)-1 | E14: =(1+E13)*IF(AND(Painel_diario!$H10="ED_JU",Painel_diario!$J10=1),EXP(Painel_diario!$L10),1)-1
